Workbook

Sheet Requirements
A1: ID | B1: Section | C1: Requirement | D1: Description | E1: Priority | F1: Design brief page | G1: In prototype | H1: Status
A2: R01 | B2: Home | C2: Club logo and name | D2: Prominently displayed | E2: Must have | F2: Home | G2: Home page | H2: =IF(G2<>"","In prototype",IF(E2="Must have","Briefed","Backlog")) -> In prototype
A3: R02 | B3: Home | C3: Mission statement or slogan | D3: A brief tagline or mission statement | E3: Must have | F3: Home | H3: =IF(G3<>"","In prototype",IF(E3="Must have","Briefed","Backlog")) -> Briefed
A4: R03 | B4: Home | C4: Latest news | D4: Headlines of the most recent club news or match results | E4: Must have | F4: Home | H4: =IF(G4<>"","In prototype",IF(E4="Must have","Briefed","Backlog")) -> Briefed
A5: R04 | B5: Home | C5: Upcoming fixtures | D5: A short list of upcoming matches | E5: Must have | F5: Home | G5: Home page | H5: =IF(G5<>"","In prototype",IF(E5="Must have","Briefed","Backlog")) -> In prototype
A6: R05 | B6: Home | C6: Featured player or match | D6: Highlight a player or a recent or next match | E6: Must have | F6: Home | H6: =IF(G6<>"","In prototype",IF(E6="Must have","Briefed","Backlog")) -> Briefed
A7: R06 | B7: Home | C7: Quick links | D7: Navigation to key sections | E7: Must have | F7: Home | G7: Navigation | H7: =IF(G7<>"","In prototype",IF(E7="Must have","Briefed","Backlog")) -> In prototype
A8: R07 | B8: About us | C8: Club history | D8: Background and history, founding date and key milestones | E8: Must have | F8: About us | H8: =IF(G8<>"","In prototype",IF(E8="Must have","Briefed","Backlog")) -> Briefed
A9: R08 | B9: About us | C9: Mission and values | D9: The core mission, vision and values of the club | E9: Must have | F9: Mission and values | G9: Navigation | H9: =IF(G9<>"","In prototype",IF(E9="Must have","Briefed","Backlog")) -> In prototype
A10: R09 | B10: About us | C10: Club achievements | D10: Trophies, titles and significant achievements | E10: Must have | F10: About us | H10: =IF(G10<>"","In prototype",IF(E10="Must have","Briefed","Backlog")) -> Briefed
A11: R10 | B11: About us | C11: Management and staff | D11: Profiles of management, coaching staff and key personnel | E11: Must have | F11: About us | H11: =IF(G11<>"","In prototype",IF(E11="Must have","Briefed","Backlog")) -> Briefed
A12: R11 | B12: About us | C12: Stadium | D12: Home ground information, location and capacity | E12: Must have | F12: About us | H12: =IF(G12<>"","In prototype",IF(E12="Must have","Briefed","Backlog")) -> Briefed
A13: R12 | B13: Team | C13: First team squad | D13: Player profiles: name, position, number, photo, bio, stats | E13: Must have | F13: Team fixtures and results | H13: =IF(G13<>"","In prototype",IF(E13="Must have","Briefed","Backlog")) -> Briefed
A14: R13 | B14: Team | C14: Coaching staff | D14: Head coach, assistants and support staff | E14: Must have | F14: Team fixtures and results | H14: =IF(G14<>"","In prototype",IF(E14="Must have","Briefed","Backlog")) -> Briefed
A15: R14 | B15: Team | C15: Youth team | D15: Profiles or list of youth and academy players | E15: Must have | F15: Team fixtures and results | H15: =IF(G15<>"","In prototype",IF(E15="Must have","Briefed","Backlog")) -> Briefed
A16: R15 | B16: Team | C16: Legends and former players | D16: Former players who made significant contributions | E16: Must have | F16: Team fixtures and results | H16: =IF(G16<>"","In prototype",IF(E16="Must have","Briefed","Backlog")) -> Briefed
A17: R16 | B17: Fixtures and results | C17: Match schedule | D17: Upcoming fixtures with date, time and opponent | E17: Must have | F17: Team fixtures and results | G17: Home page | H17: =IF(G17<>"","In prototype",IF(E17="Must have","Briefed","Backlog")) -> In prototype
A18: R17 | B18: Fixtures and results | C18: Results | D18: Recent results with scores and short summaries | E18: Must have | F18: Team fixtures and results | H18: =IF(G18<>"","In prototype",IF(E18="Must have","Briefed","Backlog")) -> Briefed
A19: R18 | B19: Fixtures and results | C19: League table | D19: Current standings in the league or competition | E19: Must have | F19: Team fixtures and results | G19: Home page | H19: =IF(G19<>"","In prototype",IF(E19="Must have","Briefed","Backlog")) -> In prototype
A20: R19 | B20: Fixtures and results | C20: Match reports | D20: Detailed reports of past matches | E20: Must have | F20: Team fixtures and results | H20: =IF(G20<>"","In prototype",IF(E20="Must have","Briefed","Backlog")) -> Briefed
A21: R20 | B21: News | C21: Club news | D21: Regular updates and articles about the club | E21: Must have | F21: Latest news | H21: =IF(G21<>"","In prototype",IF(E21="Must have","Briefed","Backlog")) -> Briefed
A22: R21 | B22: News | C22: Press releases | D22: Official statements and announcements | E22: Must have | F22: Latest news | H22: =IF(G22<>"","In prototype",IF(E22="Must have","Briefed","Backlog")) -> Briefed
A23: R22 | B23: News | C23: Interviews | D23: Interviews with players, coaches or management | E23: Must have | F23: Latest news | H23: =IF(G23<>"","In prototype",IF(E23="Must have","Briefed","Backlog")) -> Briefed
A24: R23 | B24: News | C24: Photo gallery | D24: Images from matches, training and events | E24: Must have | F24: Latest news | H24: =IF(G24<>"","In prototype",IF(E24="Must have","Briefed","Backlog")) -> Briefed
A25: R24 | B25: News | C25: Video highlights | D25: Match highlights and behind the scenes content | E25: Must have | F25: Latest news | H25: =IF(G25<>"","In prototype",IF(E25="Must have","Briefed","Backlog")) -> Briefed
A26: R25 | B26: Membership and tickets | C26: Ticket information | D26: How to buy tickets for upcoming matches, with pricing | E26: Must have | F26: Membership | H26: =IF(G26<>"","In prototype",IF(E26="Must have","Briefed","Backlog")) -> Briefed
A27: R26 | B27: Membership and tickets | C27: Season tickets | D27: Season ticket information and benefits | E27: Must have | F27: Membership | H27: =IF(G27<>"","In prototype",IF(E27="Must have","Briefed","Backlog")) -> Briefed
A28: R27 | B28: Membership and tickets | C28: Membership | D28: How to join as a member, with benefits | E28: Must have | F28: Membership | G28: Navigation | H28: =IF(G28<>"","In prototype",IF(E28="Must have","Briefed","Backlog")) -> In prototype
A29: R28 | B29: Membership and tickets | C29: Merchandise | D29: Links to the online store | E29: Must have | F29: Shop | G29: Navigation | H29: =IF(G29<>"","In prototype",IF(E29="Must have","Briefed","Backlog")) -> In prototype
A30: R29 | B30: Academy and youth | C30: Academy overview | D30: The youth academy and its objectives | E30: Later phase | H30: =IF(G30<>"","In prototype",IF(E30="Must have","Briefed","Backlog")) -> Backlog
A31: R30 | B31: Academy and youth | C31: Youth teams | D31: The different youth teams and player profiles | E31: Later phase | H31: =IF(G31<>"","In prototype",IF(E31="Must have","Briefed","Backlog")) -> Backlog
A32: R31 | B32: Academy and youth | C32: Training programmes | D32: Sessions, camps and how to join | E32: Later phase | H32: =IF(G32<>"","In prototype",IF(E32="Must have","Briefed","Backlog")) -> Backlog
A33: R32 | B33: Academy and youth | C33: Success stories | D33: Academy graduates who reached the first team | E33: Later phase | H33: =IF(G33<>"","In prototype",IF(E33="Must have","Briefed","Backlog")) -> Backlog
A34: R33 | B34: Community and outreach | C34: Community programmes | D34: The club's community involvement and charity work | E34: Later phase | H34: =IF(G34<>"","In prototype",IF(E34="Must have","Briefed","Backlog")) -> Backlog
A35: R34 | B35: Community and outreach | C35: Events | D35: Upcoming events hosted or supported by the club | E35: Later phase | H35: =IF(G35<>"","In prototype",IF(E35="Must have","Briefed","Backlog")) -> Backlog
A36: R35 | B36: Community and outreach | C36: Volunteer opportunities | D36: How fans can get involved | E36: Later phase | H36: =IF(G36<>"","In prototype",IF(E36="Must have","Briefed","Backlog")) -> Backlog
A37: R36 | B37: Community and outreach | C37: Sponsors and partners | D37: Acknowledgment of sponsors and business partners | E37: Later phase | H37: =IF(G37<>"","In prototype",IF(E37="Must have","Briefed","Backlog")) -> Backlog
A38: R37 | B38: Fan zone | C38: Supporters' club | D38: How to join the supporters' club, with benefits | E38: Must have | F38: Fan zone | H38: =IF(G38<>"","In prototype",IF(E38="Must have","Briefed","Backlog")) -> Briefed
A39: R38 | B39: Fan zone | C39: Fan forums | D39: A place for fans to discuss matches and players | E39: Must have | F39: Fan zone | H39: =IF(G39<>"","In prototype",IF(E39="Must have","Briefed","Backlog")) -> Briefed
A40: R39 | B40: Fan zone | C40: Social media links | D40: Links to the club's social media profiles | E40: Must have | F40: Fan zone | G40: Home page | H40: =IF(G40<>"","In prototype",IF(E40="Must have","Briefed","Backlog")) -> In prototype
...

Sheet Scope
A1: Section | B1: Items | C1: Priority | D1: Design brief page | E1: In prototype | F1: Briefed | G1: Backlog
A2: Home | B2: =COUNTIF(Requirements!$B$2:$B$50,A2) -> 6 | C2: Must have | D2: Home | E2: =COUNTIFS(Requirements!$B$2:$B$50,$A2,Requirements!$H$2:$H$50,"In prototype") -> 3 | F2: =COUNTIFS(Requirements!$B$2:$B$50,$A2,Requirements!$H$2:$H$50,"Briefed") -> 3 | G2: =COUNTIFS(Requirements!$B$2:$B$50,$A2,Requirements!$H$2:$H$50,"Backlog") -> 0
A3: About us | B3: =COUNTIF(Requirements!$B$2:$B$50,A3) -> 5 | C3: Must have | D3: About us | E3: =COUNTIFS(Requirements!$B$2:$B$50,$A3,Requirements!$H$2:$H$50,"In prototype") -> 1 | F3: =COUNTIFS(Requirements!$B$2:$B$50,$A3,Requirements!$H$2:$H$50,"Briefed") -> 4 | G3: =COUNTIFS(Requirements!$B$2:$B$50,$A3,Requirements!$H$2:$H$50,"Backlog") -> 0
A4: Team | B4: =COUNTIF(Requirements!$B$2:$B$50,A4) -> 4 | C4: Must have | D4: Team fixtures and results | E4: =COUNTIFS(Requirements!$B$2:$B$50,$A4,Requirements!$H$2:$H$50,"In prototype") -> 0 | F4: =COUNTIFS(Requirements!$B$2:$B$50,$A4,Requirements!$H$2:$H$50,"Briefed") -> 4 | G4: =COUNTIFS(Requirements!$B$2:$B$50,$A4,Requirements!$H$2:$H$50,"Backlog") -> 0
A5: Fixtures and results | B5: =COUNTIF(Requirements!$B$2:$B$50,A5) -> 4 | C5: Must have | D5: Team fixtures and results | E5: =COUNTIFS(Requirements!$B$2:$B$50,$A5,Requirements!$H$2:$H$50,"In prototype") -> 2 | F5: =COUNTIFS(Requirements!$B$2:$B$50,$A5,Requirements!$H$2:$H$50,"Briefed") -> 2 | G5: =COUNTIFS(Requirements!$B$2:$B$50,$A5,Requirements!$H$2:$H$50,"Backlog") -> 0
A6: News | B6: =COUNTIF(Requirements!$B$2:$B$50,A6) -> 5 | C6: Must have | D6: Latest news | E6: =COUNTIFS(Requirements!$B$2:$B$50,$A6,Requirements!$H$2:$H$50,"In prototype") -> 0 | F6: =COUNTIFS(Requirements!$B$2:$B$50,$A6,Requirements!$H$2:$H$50,"Briefed") -> 5 | G6: =COUNTIFS(Requirements!$B$2:$B$50,$A6,Requirements!$H$2:$H$50,"Backlog") -> 0
A7: Membership and tickets | B7: =COUNTIF(Requirements!$B$2:$B$50,A7) -> 4 | C7: Must have | D7: Membership | E7: =COUNTIFS(Requirements!$B$2:$B$50,$A7,Requirements!$H$2:$H$50,"In prototype") -> 2 | F7: =COUNTIFS(Requirements!$B$2:$B$50,$A7,Requirements!$H$2:$H$50,"Briefed") -> 2 | G7: =COUNTIFS(Requirements!$B$2:$B$50,$A7,Requirements!$H$2:$H$50,"Backlog") -> 0
A8: Academy and youth | B8: =COUNTIF(Requirements!$B$2:$B$50,A8) -> 4 | C8: Later phase | E8: =COUNTIFS(Requirements!$B$2:$B$50,$A8,Requirements!$H$2:$H$50,"In prototype") -> 0 | F8: =COUNTIFS(Requirements!$B$2:$B$50,$A8,Requirements!$H$2:$H$50,"Briefed") -> 0 | G8: =COUNTIFS(Requirements!$B$2:$B$50,$A8,Requirements!$H$2:$H$50,"Backlog") -> 4
A9: Community and outreach | B9: =COUNTIF(Requirements!$B$2:$B$50,A9) -> 4 | C9: Later phase | E9: =COUNTIFS(Requirements!$B$2:$B$50,$A9,Requirements!$H$2:$H$50,"In prototype") -> 0 | F9: =COUNTIFS(Requirements!$B$2:$B$50,$A9,Requirements!$H$2:$H$50,"Briefed") -> 0 | G9: =COUNTIFS(Requirements!$B$2:$B$50,$A9,Requirements!$H$2:$H$50,"Backlog") -> 4
A10: Fan zone | B10: =COUNTIF(Requirements!$B$2:$B$50,A10) -> 4 | C10: Must have | D10: Fan zone | E10: =COUNTIFS(Requirements!$B$2:$B$50,$A10,Requirements!$H$2:$H$50,"In prototype") -> 1 | F10: =COUNTIFS(Requirements!$B$2:$B$50,$A10,Requirements!$H$2:$H$50,"Briefed") -> 3 | G10: =COUNTIFS(Requirements!$B$2:$B$50,$A10,Requirements!$H$2:$H$50,"Backlog") -> 0
A11: Contact us | B11: =COUNTIF(Requirements!$B$2:$B$50,A11) -> 4 | C11: Must have | D11: Contact us | E11: =COUNTIFS(Requirements!$B$2:$B$50,$A11,Requirements!$H$2:$H$50,"In prototype") -> 1 | F11: =COUNTIFS(Requirements!$B$2:$B$50,$A11,Requirements!$H$2:$H$50,"Briefed") -> 3 | G11: =COUNTIFS(Requirements!$B$2:$B$50,$A11,Requirements!$H$2:$H$50,"Backlog") -> 0
A12: Sponsorship and partnerships | B12: =COUNTIF(Requirements!$B$2:$B$50,A12) -> 3 | C12: Must have | D12: Sponsorship and partnerships | E12: =COUNTIFS(Requirements!$B$2:$B$50,$A12,Requirements!$H$2:$H$50,"In prototype") -> 1 | F12: =COUNTIFS(Requirements!$B$2:$B$50,$A12,Requirements!$H$2:$H$50,"Briefed") -> 2 | G12: =COUNTIFS(Requirements!$B$2:$B$50,$A12,Requirements!$H$2:$H$50,"Backlog") -> 0
A13: Shop | B13: =COUNTIF(Requirements!$B$2:$B$50,A13) -> 2 | C13: Must have | D13: Shop | E13: =COUNTIFS(Requirements!$B$2:$B$50,$A13,Requirements!$H$2:$H$50,"In prototype") -> 1 | F13: =COUNTIFS(Requirements!$B$2:$B$50,$A13,Requirements!$H$2:$H$50,"Briefed") -> 1 | G13: =COUNTIFS(Requirements!$B$2:$B$50,$A13,Requirements!$H$2:$H$50,"Backlog") -> 0
A14: Total | B14: =SUM(B2:B13) -> 49 | C14: =COUNTIF(C2:C13,"Must have")&" must have sections" -> 10 must have sections | E14: =SUM(E2:E13) -> 12 | F14: =SUM(F2:F13) -> 29 | G14: =SUM(G2:G13) -> 8

Sheet Plan
A1: Project plan | H1: Week 1 | M1: Week 2
A2: ID | B2: Task | C2: Owner | D2: Phase | E2: Start | F2: End | G2: Status | H2: 1 | I2: 2 | J2: 3 | K2: 4 | L2: 5 | M2: 6 | N2: 7 | O2: 8 | P2: 9 | Q2: 10
A3: T01 | B3: Kickoff and discovery call request | C3: Business Analyst | D3: Discover | E3: 1 | F3: 1 | G3: Done
A4: T02 | B4: Discovery call with football manager | C4: Business Analyst, Football manager | D4: Discover | E4: 2 | F4: 2 | G4: Done
A5: T03 | B5: Agree brand palette | C5: Football manager | D5: Discover | E5: 2 | F5: 2 | G5: Done
A6: T04 | B6: Write website structure document | C6: Business Analyst | D6: Define | E6: 3 | F6: 3 | G6: Done
A7: T05 | B7: Collect club content: mission, vision, values, history | C7: Business Analyst, Football manager | D7: Define | E7: 3 | F7: 6 | G7: Done
A8: T06 | B8: Prioritise scope into must have pages | C8: Business Analyst | D8: Define | E8: 6 | F8: 7 | G8: Done
A9: T07 | B9: Issue design brief to designer | C9: Business Analyst | D9: Design | E9: 7 | F9: 7 | G9: Done
A10: T08 | B10: Build clickable Figma prototype | C10: UI/UX designer | D10: Design | E10: 7 | F10: 9 | G10: Done
A11: T09 | B11: Prototype review with football manager | C11: Business Analyst, Football manager | D11: Review | E11: 9 | F11: 9 | G11: Done
A12: T10 | B12: Apply review changes from the football manager | C12: UI/UX designer | D12: Review | E12: 9 | F12: 10 | G12: In progress
A13: T11 | B13: Send revised prototype for sign off | C13: Business Analyst | D13: Review | E13: 10 | F13: 10 | G13: To do
B15: Tasks done | C15: =COUNTIF(G3:G13,"Done")&" of "&COUNTA(G3:G13) -> 9 of 11
B16: Days planned | C16: =MAX(F3:F13) -> 10

Sheet Board
A1: Backlog | B1: To do | C1: In progress | D1: Done
A2: Academy and youth section (later phase) | B2: Add league and accreditation marks | C2: Fix prototype link on mobile | D2: Discovery call with football manager
A3: Community and outreach section (later phase) | B3: Link the club's media channel | D3: Collect club content
B4: Send revised prototype for sign off | D4: Write website structure document
D5: Agree brand palette and colour priority
D6: Prioritise scope into must have pages
D7: Issue design brief to designer
D8: Build clickable Figma prototype
D9: Prototype review with football manager
A11: Cards
A12: =COUNTA(A2:A9) -> 2 | B12: =COUNTA(B2:B9) -> 3 | C12: =COUNTA(C2:C9) -> 1 | D12: =COUNTA(D2:D9) -> 8
