Workbook

Sheet README
B1: Salesforce Admin Dashboard: cleaned rebuild
B2: Cleaned file: real names, figures and records replaced with synthetic data of the same structure.
B4: What this file does
B6: Scores the open general opportunities for the current quarter on five data quality checks, region by region, and turns each region into one word: REVIEW or FAIR. It replaced a monthly manual sweep of raw Salesforce exports. This copy runs on synthetic opportunities with the same tabs, columns and formulas.
B7: The five checks
B9: • Unassigned forecast category (red flag above 20%).
B10: • Missing forecast technology MRR (review above 15%).
B11: • Missing billing address (review above 10%).
B12: • Missing billing address and BP ID together (review above 5%).
B13: • Close date already in the past (stale pipeline above 5%).
B14: Tabs
B16: • Open General Opps CFY: the Salesforce extract. SAP Region comes from the office through the lookup table; six flag columns score every row.
... B27: All accounts, owners, IDs, BP IDs, addresses and values are invented.

Sheet Summary Metrics
A1: Summary metrics
A3: Current Quarter | B3: ='SFDC Admin Dashboard'!B4 -> Q3-2025
A8: Region | B8: Total opps | C8: % missing forecast category | D8: % missing forecast tech MRR | E8: % missing address | F8: % missing address and BP ID | G8: % past close dates | H8: Attention needed
A9: NA | B9: ='SFDC Admin Dashboard'!B8 -> 21 | C9: ='SFDC Admin Dashboard'!D8 -> 0.14285714 | D9: ='SFDC Admin Dashboard'!D32 -> 0.047619048 | E9: ='SFDC Admin Dashboard'!D44 -> 0.42857143 | F9: ='SFDC Admin Dashboard'!F44 -> 0.33333333 | G9: ='SFDC Admin Dashboard'!D56 -> 0.047619048 | H9: =IF(OR(C9>20%,D9>15%,E9>10%,F9>5%,G9>5%),"REVIEW","FAIR") -> REVIEW
A10: LATAM | B10: ='SFDC Admin Dashboard'!B9 -> 14 | C10: ='SFDC Admin Dashboard'!D9 -> 0.21428571 | D10: ='SFDC Admin Dashboard'!D33 -> 0.071428571 | E10: ='SFDC Admin Dashboard'!D45 -> 0.78571429 | F10: ='SFDC Admin Dashboard'!F45 -> 0.35714286 | G10: ='SFDC Admin Dashboard'!D57 -> 0.071428571 | H10: =IF(OR(C10>20%,D10>15%,E10>10%,F10>5%,G10>5%),"REVIEW","FAIR") -> REVIEW
A11: EMEA N | B11: ='SFDC Admin Dashboard'!B10 -> 32 | C11: ='SFDC Admin Dashboard'!D10 -> 0.03125 | D11: ='SFDC Admin Dashboard'!D34 -> 0.09375 | E11: ='SFDC Admin Dashboard'!D46 -> 0 | F11: ='SFDC Admin Dashboard'!F46 -> 0 | G11: ='SFDC Admin Dashboard'!D58 -> 0 | H11: =IF(OR(C11>20%,D11>15%,E11>10%,F11>5%,G11>5%),"REVIEW","FAIR") -> FAIR
A12: EMEA S | B12: ='SFDC Admin Dashboard'!B11 -> 11 | C12: ='SFDC Admin Dashboard'!D11 -> 0.090909091 | D12: ='SFDC Admin Dashboard'!D35 -> 0.18181818 | E12: ='SFDC Admin Dashboard'!D47 -> 0 | F12: ='SFDC Admin Dashboard'!F47 -> 0 | G12: ='SFDC Admin Dashboard'!D59 -> 0 | H12: =IF(OR(C12>20%,D12>15%,E12>10%,F12>5%,G12>5%),"REVIEW","FAIR") -> REVIEW
A13: MEE | B13: ='SFDC Admin Dashboard'!B12 -> 19 | C13: ='SFDC Admin Dashboard'!D12 -> 0.052631579 | D13: ='SFDC Admin Dashboard'!D36 -> 0.052631579 | E13: ='SFDC Admin Dashboard'!D48 -> 0.63157895 | F13: ='SFDC Admin Dashboard'!F48 -> 0.26315789 | G13: ='SFDC Admin Dashboard'!D60 -> 0.31578947 | H13: =IF(OR(C13>20%,D13>15%,E13>10%,F13>5%,G13>5%),"REVIEW","FAIR") -> REVIEW
A14: APJ | B14: ='SFDC Admin Dashboard'!B13 -> 8 | C14: ='SFDC Admin Dashboard'!D13 -> 0 | D14: ='SFDC Admin Dashboard'!D37 -> 0.125 | E14: ='SFDC Admin Dashboard'!D49 -> 0 | F14: ='SFDC Admin Dashboard'!F49 -> 0 | G14: ='SFDC Admin Dashboard'!D61 -> 0 | H14: =IF(OR(C14>20%,D14>15%,E14>10%,F14>5%,G14>5%),"REVIEW","FAIR") -> FAIR
A15: GCN | B15: ='SFDC Admin Dashboard'!B14 -> 10 | C15: ='SFDC Admin Dashboard'!D14 -> 0.1 | D15: ='SFDC Admin Dashboard'!D38 -> 0.1 | E15: ='SFDC Admin Dashboard'!D50 -> 1 | F15: ='SFDC Admin Dashboard'!F50 -> 0.3 | G15: ='SFDC Admin Dashboard'!D62 -> 0 | H15: =IF(OR(C15>20%,D15>15%,E15>10%,F15>5%,G15>5%),"REVIEW","FAIR") -> REVIEW
A16: Global | B16: ='SFDC Admin Dashboard'!B15 -> 115 | C16: ='SFDC Admin Dashboard'!D15 -> 0.086956522 | D16: ='SFDC Admin Dashboard'!D39 -> 0.086956522 | E16: ='SFDC Admin Dashboard'!D51 -> 0.36521739 | F16: ='SFDC Admin Dashboard'!F51 -> 0.17391304 | G16: ='SFDC Admin Dashboard'!D63 -> 0.069565217 | H16: =IF(OR(C16>20%,D16>15%,E16>10%,F16>5%,G16>5%),"REVIEW","FAIR") -> REVIEW
A19: This table shows data quality and forecast readiness for each region in the selected quarter, so sales and revenue operations can see where to act first.
A20: % missing forecast category: above 20% is a red flag.
A21: % missing forecast tech MRR: above 15% needs review.
A22: % missing address: above 10% reduces conversion confidence. Address and BP ID together: above 5%.
A23: % past close dates: above 5% suggests stale pipeline.
A24: REVIEW means a revenue operations or sales manager needs to act now. FAIR means the region is inside every threshold.

Sheet SFDC Admin Dashboard
A2: =B4&" NBS SFDC ADMIN DASHBOARD" -> Q3-2025 NBS SFDC ADMIN DASHBOARD
A4: Current Quarter | B4: Q3-2025
A6: Open opportunities per forecast category
A7: Region | B7: Total open general opps | C7: Unassigned forecast | D7: % unassigned forecast
A8: NA | B8: =COUNTIFS('Open General Opps CFY'!$C$2:$C$142,$A8,'Open General Opps CFY'!$I$2:$I$142,$B$4) -> 21 | C8: =COUNTIFS('Open General Opps CFY'!$C$2:$C$142,$A8,'Open General Opps CFY'!$I$2:$I$142,$B$4,'Open General Opps CFY'!$P$2:$P$142,1) -> 3 | D8: =IF(B8=0,0,C8/B8) -> 0.14285714
A9: LATAM | B9: =COUNTIFS('Open General Opps CFY'!$C$2:$C$142,$A9,'Open General Opps CFY'!$I$2:$I$142,$B$4) -> 14 | C9: =COUNTIFS('Open General Opps CFY'!$C$2:$C$142,$A9,'Open General Opps CFY'!$I$2:$I$142,$B$4,'Open General Opps CFY'!$P$2:$P$142,1) -> 3 | D9: =IF(B9=0,0,C9/B9) -> 0.21428571
A10: EMEA N | B10: =COUNTIFS('Open General Opps CFY'!$C$2:$C$142,$A10,'Open General Opps CFY'!$I$2:$I$142,$B$4) -> 32 | C10: =COUNTIFS('Open General Opps CFY'!$C$2:$C$142,$A10,'Open General Opps CFY'!$I$2:$I$142,$B$4,'Open General Opps CFY'!$P$2:$P$142,1) -> 1 | D10: =IF(B10=0,0,C10/B10) -> 0.03125
A11: EMEA S | B11: =COUNTIFS('Open General Opps CFY'!$C$2:$C$142,$A11,'Open General Opps CFY'!$I$2:$I$142,$B$4) -> 11 | C11: =COUNTIFS('Open General Opps CFY'!$C$2:$C$142,$A11,'Open General Opps CFY'!$I$2:$I$142,$B$4,'Open General Opps CFY'!$P$2:$P$142,1) -> 1 | D11: =IF(B11=0,0,C11/B11) -> 0.090909091
A12: MEE | B12: =COUNTIFS('Open General Opps CFY'!$C$2:$C$142,$A12,'Open General Opps CFY'!$I$2:$I$142,$B$4) -> 19 | C12: =COUNTIFS('Open General Opps CFY'!$C$2:$C$142,$A12,'Open General Opps CFY'!$I$2:$I$142,$B$4,'Open General Opps CFY'!$P$2:$P$142,1) -> 1 | D12: =IF(B12=0,0,C12/B12) -> 0.052631579
A13: APJ | B13: =COUNTIFS('Open General Opps CFY'!$C$2:$C$142,$A13,'Open General Opps CFY'!$I$2:$I$142,$B$4) -> 8 | C13: =COUNTIFS('Open General Opps CFY'!$C$2:$C$142,$A13,'Open General Opps CFY'!$I$2:$I$142,$B$4,'Open General Opps CFY'!$P$2:$P$142,1) -> 0 | D13: =IF(B13=0,0,C13/B13) -> 0
A14: GCN | B14: =COUNTIFS('Open General Opps CFY'!$C$2:$C$142,$A14,'Open General Opps CFY'!$I$2:$I$142,$B$4) -> 10 | C14: =COUNTIFS('Open General Opps CFY'!$C$2:$C$142,$A14,'Open General Opps CFY'!$I$2:$I$142,$B$4,'Open General Opps CFY'!$P$2:$P$142,1) -> 1 | D14: =IF(B14=0,0,C14/B14) -> 0.1
A15: Global | B15: =SUM(B8:B14) -> 115 | C15: =SUM(C8:C14) -> 10 | D15: =IF(B15=0,0,C15/B15) -> 0.086956522
A18: Open opportunities per stage
A19: Region | B19: Business chemistry & Scoping | C19: Solution Presentation | D19: Tech Agreement | E19: Commercial Agreement | F19: Contracting
A20: NA | B20: =COUNTIFS('Open General Opps CFY'!$C$2:$C$142,$A20,'Open General Opps CFY'!$I$2:$I$142,$B$4,'Open General Opps CFY'!$F$2:$F$142,"Business chemistry & Scoping") -> 4 | C20: =COUNTIFS('Open General Opps CFY'!$C$2:$C$142,$A20,'Open General Opps CFY'!$I$2:$I$142,$B$4,'Open General Opps CFY'!$F$2:$F$142,"Solution Presentation") -> 8 | D20: =COUNTIFS('Open General Opps CFY'!$C$2:$C$142,$A20,'Open General Opps CFY'!$I$2:$I$142,$B$4,'Open General Opps CFY'!$F$2:$F$142,"Tech Agreement") -> 4 | E20: =COUNTIFS('Open General Opps CFY'!$C$2:$C$142,$A20,'Open General Opps CFY'!$I$2:$I$142,$B$4,'Open General Opps CFY'!$F$2:$F$142,"Commercial Agreement") -> 4 | F20: =COUNTIFS('Open General Opps CFY'!$C$2:$C$142,$A20,'Open General Opps CFY'!$I$2:$I$142,$B$4,'Open General Opps CFY'!$F$2:$F$142,"Contracting") -> 1
A21: LATAM | B21: =COUNTIFS('Open General Opps CFY'!$C$2:$C$142,$A21,'Open General Opps CFY'!$I$2:$I$142,$B$4,'Open General Opps CFY'!$F$2:$F$142,"Business chemistry & Scoping") -> 3 | C21: =COUNTIFS('Open General Opps CFY'!$C$2:$C$142,$A21,'Open General Opps CFY'!$I$2:$I$142,$B$4,'Open General Opps CFY'!$F$2:$F$142,"Solution Presentation") -> 5 | D21: =COUNTIFS('Open General Opps CFY'!$C$2:$C$142,$A21,'Open General Opps CFY'!$I$2:$I$142,$B$4,'Open General Opps CFY'!$F$2:$F$142,"Tech Agreement") -> 1 | E21: =COUNTIFS('Open General Opps CFY'!$C$2:$C$142,$A21,'Open General Opps CFY'!$I$2:$I$142,$B$4,'Open General Opps CFY'!$F$2:$F$142,"Commercial Agreement") -> 4 | F21: =COUNTIFS('Open General Opps CFY'!$C$2:$C$142,$A21,'Open General Opps CFY'!$I$2:$I$142,$B$4,'Open General Opps CFY'!$F$2:$F$142,"Contracting") -> 1
A22: EMEA N | B22: =COUNTIFS('Open General Opps CFY'!$C$2:$C$142,$A22,'Open General Opps CFY'!$I$2:$I$142,$B$4,'Open General Opps CFY'!$F$2:$F$142,"Business chemistry & Scoping") -> 12 | C22: =COUNTIFS('Open General Opps CFY'!$C$2:$C$142,$A22,'Open General Opps CFY'!$I$2:$I$142,$B$4,'Open General Opps CFY'!$F$2:$F$142,"Solution Presentation") -> 8 | D22: =COUNTIFS('Open General Opps CFY'!$C$2:$C$142,$A22,'Open General Opps CFY'!$I$2:$I$142,$B$4,'Open General Opps CFY'!$F$2:$F$142,"Tech Agreement") -> 6 | E22: =COUNTIFS('Open General Opps CFY'!$C$2:$C$142,$A22,'Open General Opps CFY'!$I$2:$I$142,$B$4,'Open General Opps CFY'!$F$2:$F$142,"Commercial Agreement") -> 5 | F22: =COUNTIFS('Open General Opps CFY'!$C$2:$C$142,$A22,'Open General Opps CFY'!$I$2:$I$142,$B$4,'Open General Opps CFY'!$F$2:$F$142,"Contracting") -> 1
A23: EMEA S | B23: =COUNTIFS('Open General Opps CFY'!$C$2:$C$142,$A23,'Open General Opps CFY'!$I$2:$I$142,$B$4,'Open General Opps CFY'!$F$2:$F$142,"Business chemistry & Scoping") -> 5 | C23: =COUNTIFS('Open General Opps CFY'!$C$2:$C$142,$A23,'Open General Opps CFY'!$I$2:$I$142,$B$4,'Open General Opps CFY'!$F$2:$F$142,"Solution Presentation") -> 5 | D23: =COUNTIFS('Open General Opps CFY'!$C$2:$C$142,$A23,'Open General Opps CFY'!$I$2:$I$142,$B$4,'Open General Opps CFY'!$F$2:$F$142,"Tech Agreement") -> 1 | E23: =COUNTIFS('Open General Opps CFY'!$C$2:$C$142,$A23,'Open General Opps CFY'!$I$2:$I$142,$B$4,'Open General Opps CFY'!$F$2:$F$142,"Commercial Agreement") -> 0 | F23: =COUNTIFS('Open General Opps CFY'!$C$2:$C$142,$A23,'Open General Opps CFY'!$I$2:$I$142,$B$4,'Open General Opps CFY'!$F$2:$F$142,"Contracting") -> 0
A24: MEE | B24: =COUNTIFS('Open General Opps CFY'!$C$2:$C$142,$A24,'Open General Opps CFY'!$I$2:$I$142,$B$4,'Open General Opps CFY'!$F$2:$F$142,"Business chemistry & Scoping") -> 3 | C24: =COUNTIFS('Open General Opps CFY'!$C$2:$C$142,$A24,'Open General Opps CFY'!$I$2:$I$142,$B$4,'Open General Opps CFY'!$F$2:$F$142,"Solution Presentation") -> 6 | D24: =COUNTIFS('Open General Opps CFY'!$C$2:$C$142,$A24,'Open General Opps CFY'!$I$2:$I$142,$B$4,'Open General Opps CFY'!$F$2:$F$142,"Tech Agreement") -> 3 | E24: =COUNTIFS('Open General Opps CFY'!$C$2:$C$142,$A24,'Open General Opps CFY'!$I$2:$I$142,$B$4,'Open General Opps CFY'!$F$2:$F$142,"Commercial Agreement") -> 4 | F24: =COUNTIFS('Open General Opps CFY'!$C$2:$C$142,$A24,'Open General Opps CFY'!$I$2:$I$142,$B$4,'Open General Opps CFY'!$F$2:$F$142,"Contracting") -> 3
A25: APJ | B25: =COUNTIFS('Open General Opps CFY'!$C$2:$C$142,$A25,'Open General Opps CFY'!$I$2:$I$142,$B$4,'Open General Opps CFY'!$F$2:$F$142,"Business chemistry & Scoping") -> 3 | C25: =COUNTIFS('Open General Opps CFY'!$C$2:$C$142,$A25,'Open General Opps CFY'!$I$2:$I$142,$B$4,'Open General Opps CFY'!$F$2:$F$142,"Solution Presentation") -> 0 | D25: =COUNTIFS('Open General Opps CFY'!$C$2:$C$142,$A25,'Open General Opps CFY'!$I$2:$I$142,$B$4,'Open General Opps CFY'!$F$2:$F$142,"Tech Agreement") -> 2 | E25: =COUNTIFS('Open General Opps CFY'!$C$2:$C$142,$A25,'Open General Opps CFY'!$I$2:$I$142,$B$4,'Open General Opps CFY'!$F$2:$F$142,"Commercial Agreement") -> 3 | F25: =COUNTIFS('Open General Opps CFY'!$C$2:$C$142,$A25,'Open General Opps CFY'!$I$2:$I$142,$B$4,'Open General Opps CFY'!$F$2:$F$142,"Contracting") -> 0
A26: GCN | B26: =COUNTIFS('Open General Opps CFY'!$C$2:$C$142,$A26,'Open General Opps CFY'!$I$2:$I$142,$B$4,'Open General Opps CFY'!$F$2:$F$142,"Business chemistry & Scoping") -> 5 | C26: =COUNTIFS('Open General Opps CFY'!$C$2:$C$142,$A26,'Open General Opps CFY'!$I$2:$I$142,$B$4,'Open General Opps CFY'!$F$2:$F$142,"Solution Presentation") -> 1 | D26: =COUNTIFS('Open General Opps CFY'!$C$2:$C$142,$A26,'Open General Opps CFY'!$I$2:$I$142,$B$4,'Open General Opps CFY'!$F$2:$F$142,"Tech Agreement") -> 1 | E26: =COUNTIFS('Open General Opps CFY'!$C$2:$C$142,$A26,'Open General Opps CFY'!$I$2:$I$142,$B$4,'Open General Opps CFY'!$F$2:$F$142,"Commercial Agreement") -> 3 | F26: =COUNTIFS('Open General Opps CFY'!$C$2:$C$142,$A26,'Open General Opps CFY'!$I$2:$I$142,$B$4,'Open General Opps CFY'!$F$2:$F$142,"Contracting") -> 0
A27: Global | B27: =SUM(B20:B26) -> 35 | C27: =SUM(C20:C26) -> 33 | D27: =SUM(D20:D26) -> 18 | E27: =SUM(E20:E26) -> 23 | F27: =SUM(F20:F26) -> 6
A30: Open general opportunities missing forecast tech MRR
A31: Region | B31: Total open general opps | C31: Missing forecast tech MRR | D31: % missing tech MRR | E31: SAP Paper opps | F31: SAP Paper missing MRR
A32: NA | B32: =COUNTIFS('Open General Opps CFY'!$C$2:$C$142,$A32,'Open General Opps CFY'!$I$2:$I$142,$B$4) -> 21 | C32: =COUNTIFS('Open General Opps CFY'!$C$2:$C$142,$A32,'Open General Opps CFY'!$I$2:$I$142,$B$4,'Open General Opps CFY'!$Q$2:$Q$142,1) -> 1 | D32: =IF(B32=0,0,C32/B32) -> 0.047619048 | E32: =COUNTIFS('Open General Opps CFY'!$C$2:$C$142,$A32,'Open General Opps CFY'!$I$2:$I$142,$B$4,'Open General Opps CFY'!$J$2:$J$142,TRUE()) -> 6 | F32: =COUNTIFS('Open General Opps CFY'!$C$2:$C$142,$A32,'Open General Opps CFY'!$I$2:$I$142,$B$4,'Open General Opps CFY'!$R$2:$R$142,1) -> 0
A33: LATAM | B33: =COUNTIFS('Open General Opps CFY'!$C$2:$C$142,$A33,'Open General Opps CFY'!$I$2:$I$142,$B$4) -> 14 | C33: =COUNTIFS('Open General Opps CFY'!$C$2:$C$142,$A33,'Open General Opps CFY'!$I$2:$I$142,$B$4,'Open General Opps CFY'!$Q$2:$Q$142,1) -> 1 | D33: =IF(B33=0,0,C33/B33) -> 0.071428571 | E33: =COUNTIFS('Open General Opps CFY'!$C$2:$C$142,$A33,'Open General Opps CFY'!$I$2:$I$142,$B$4,'Open General Opps CFY'!$J$2:$J$142,TRUE()) -> 9 | F33: =COUNTIFS('Open General Opps CFY'!$C$2:$C$142,$A33,'Open General Opps CFY'!$I$2:$I$142,$B$4,'Open General Opps CFY'!$R$2:$R$142,1) -> 0
A34: EMEA N | B34: =COUNTIFS('Open General Opps CFY'!$C$2:$C$142,$A34,'Open General Opps CFY'!$I$2:$I$142,$B$4) -> 32 | C34: =COUNTIFS('Open General Opps CFY'!$C$2:$C$142,$A34,'Open General Opps CFY'!$I$2:$I$142,$B$4,'Open General Opps CFY'!$Q$2:$Q$142,1) -> 3 | D34: =IF(B34=0,0,C34/B34) -> 0.09375 | E34: =COUNTIFS('Open General Opps CFY'!$C$2:$C$142,$A34,'Open General Opps CFY'!$I$2:$I$142,$B$4,'Open General Opps CFY'!$J$2:$J$142,TRUE()) -> 12 | F34: =COUNTIFS('Open General Opps CFY'!$C$2:$C$142,$A34,'Open General Opps CFY'!$I$2:$I$142,$B$4,'Open General Opps CFY'!$R$2:$R$142,1) -> 1
A35: EMEA S | B35: =COUNTIFS('Open General Opps CFY'!$C$2:$C$142,$A35,'Open General Opps CFY'!$I$2:$I$142,$B$4) -> 11 | C35: =COUNTIFS('Open General Opps CFY'!$C$2:$C$142,$A35,'Open General Opps CFY'!$I$2:$I$142,$B$4,'Open General Opps CFY'!$Q$2:$Q$142,1) -> 2 | D35: =IF(B35=0,0,C35/B35) -> 0.18181818 | E35: =COUNTIFS('Open General Opps CFY'!$C$2:$C$142,$A35,'Open General Opps CFY'!$I$2:$I$142,$B$4,'Open General Opps CFY'!$J$2:$J$142,TRUE()) -> 5 | F35: =COUNTIFS('Open General Opps CFY'!$C$2:$C$142,$A35,'Open General Opps CFY'!$I$2:$I$142,$B$4,'Open General Opps CFY'!$R$2:$R$142,1) -> 0
A36: MEE | B36: =COUNTIFS('Open General Opps CFY'!$C$2:$C$142,$A36,'Open General Opps CFY'!$I$2:$I$142,$B$4) -> 19 | C36: =COUNTIFS('Open General Opps CFY'!$C$2:$C$142,$A36,'Open General Opps CFY'!$I$2:$I$142,$B$4,'Open General Opps CFY'!$Q$2:$Q$142,1) -> 1 | D36: =IF(B36=0,0,C36/B36) -> 0.052631579 | E36: =COUNTIFS('Open General Opps CFY'!$C$2:$C$142,$A36,'Open General Opps CFY'!$I$2:$I$142,$B$4,'Open General Opps CFY'!$J$2:$J$142,TRUE()) -> 10 | F36: =COUNTIFS('Open General Opps CFY'!$C$2:$C$142,$A36,'Open General Opps CFY'!$I$2:$I$142,$B$4,'Open General Opps CFY'!$R$2:$R$142,1) -> 1
A37: APJ | B37: =COUNTIFS('Open General Opps CFY'!$C$2:$C$142,$A37,'Open General Opps CFY'!$I$2:$I$142,$B$4) -> 8 | C37: =COUNTIFS('Open General Opps CFY'!$C$2:$C$142,$A37,'Open General Opps CFY'!$I$2:$I$142,$B$4,'Open General Opps CFY'!$Q$2:$Q$142,1) -> 1 | D37: =IF(B37=0,0,C37/B37) -> 0.125 | E37: =COUNTIFS('Open General Opps CFY'!$C$2:$C$142,$A37,'Open General Opps CFY'!$I$2:$I$142,$B$4,'Open General Opps CFY'!$J$2:$J$142,TRUE()) -> 2 | F37: =COUNTIFS('Open General Opps CFY'!$C$2:$C$142,$A37,'Open General Opps CFY'!$I$2:$I$142,$B$4,'Open General Opps CFY'!$R$2:$R$142,1) -> 0
A38: GCN | B38: =COUNTIFS('Open General Opps CFY'!$C$2:$C$142,$A38,'Open General Opps CFY'!$I$2:$I$142,$B$4) -> 10 | C38: =COUNTIFS('Open General Opps CFY'!$C$2:$C$142,$A38,'Open General Opps CFY'!$I$2:$I$142,$B$4,'Open General Opps CFY'!$Q$2:$Q$142,1) -> 1 | D38: =IF(B38=0,0,C38/B38) -> 0.1 | E38: =COUNTIFS('Open General Opps CFY'!$C$2:$C$142,$A38,'Open General Opps CFY'!$I$2:$I$142,$B$4,'Open General Opps CFY'!$J$2:$J$142,TRUE()) -> 4 | F38: =COUNTIFS('Open General Opps CFY'!$C$2:$C$142,$A38,'Open General Opps CFY'!$I$2:$I$142,$B$4,'Open General Opps CFY'!$R$2:$R$142,1) -> 1
A39: Global | B39: =SUM(B32:B38) -> 115 | C39: =SUM(C32:C38) -> 10 | D39: =IF(B39=0,0,C39/B39) -> 0.086956522 | E39: =SUM(E32:E38) -> 48 | F39: =SUM(F32:F38) -> 3
A42: Billing address and BP ID
A43: Region | B43: Total open general opps | C43: Missing billing address | D43: % missing address | E43: Missing address and BP ID | F43: % missing address and BP ID
A44: NA | B44: =COUNTIFS('Open General Opps CFY'!$C$2:$C$142,$A44,'Open General Opps CFY'!$I$2:$I$142,$B$4) -> 21 | C44: =COUNTIFS('Open General Opps CFY'!$C$2:$C$142,$A44,'Open General Opps CFY'!$I$2:$I$142,$B$4,'Open General Opps CFY'!$S$2:$S$142,1) -> 9 | D44: =IF(B44=0,0,C44/B44) -> 0.42857143 | E44: =COUNTIFS('Open General Opps CFY'!$C$2:$C$142,$A44,'Open General Opps CFY'!$I$2:$I$142,$B$4,'Open General Opps CFY'!$T$2:$T$142,1) -> 7 | F44: =IF(B44=0,0,E44/B44) -> 0.33333333
A45: LATAM | B45: =COUNTIFS('Open General Opps CFY'!$C$2:$C$142,$A45,'Open General Opps CFY'!$I$2:$I$142,$B$4) -> 14 | C45: =COUNTIFS('Open General Opps CFY'!$C$2:$C$142,$A45,'Open General Opps CFY'!$I$2:$I$142,$B$4,'Open General Opps CFY'!$S$2:$S$142,1) -> 11 | D45: =IF(B45=0,0,C45/B45) -> 0.78571429 | E45: =COUNTIFS('Open General Opps CFY'!$C$2:$C$142,$A45,'Open General Opps CFY'!$I$2:$I$142,$B$4,'Open General Opps CFY'!$T$2:$T$142,1) -> 5 | F45: =IF(B45=0,0,E45/B45) -> 0.35714286
A46: EMEA N | B46: =COUNTIFS('Open General Opps CFY'!$C$2:$C$142,$A46,'Open General Opps CFY'!$I$2:$I$142,$B$4) -> 32 | C46: =COUNTIFS('Open General Opps CFY'!$C$2:$C$142,$A46,'Open General Opps CFY'!$I$2:$I$142,$B$4,'Open General Opps CFY'!$S$2:$S$142,1) -> 0 | D46: =IF(B46=0,0,C46/B46) -> 0 | E46: =COUNTIFS('Open General Opps CFY'!$C$2:$C$142,$A46,'Open General Opps CFY'!$I$2:$I$142,$B$4,'Open General Opps CFY'!$T$2:$T$142,1) -> 0 | F46: =IF(B46=0,0,E46/B46) -> 0
A47: EMEA S | B47: =COUNTIFS('Open General Opps CFY'!$C$2:$C$142,$A47,'Open General Opps CFY'!$I$2:$I$142,$B$4) -> 11 | C47: =COUNTIFS('Open General Opps CFY'!$C$2:$C$142,$A47,'Open General Opps CFY'!$I$2:$I$142,$B$4,'Open General Opps CFY'!$S$2:$S$142,1) -> 0 | D47: =IF(B47=0,0,C47/B47) -> 0 | E47: =COUNTIFS('Open General Opps CFY'!$C$2:$C$142,$A47,'Open General Opps CFY'!$I$2:$I$142,$B$4,'Open General Opps CFY'!$T$2:$T$142,1) -> 0 | F47: =IF(B47=0,0,E47/B47) -> 0
A48: MEE | B48: =COUNTIFS('Open General Opps CFY'!$C$2:$C$142,$A48,'Open General Opps CFY'!$I$2:$I$142,$B$4) -> 19 | C48: =COUNTIFS('Open General Opps CFY'!$C$2:$C$142,$A48,'Open General Opps CFY'!$I$2:$I$142,$B$4,'Open General Opps CFY'!$S$2:$S$142,1) -> 12 | D48: =IF(B48=0,0,C48/B48) -> 0.63157895 | E48: =COUNTIFS('Open General Opps CFY'!$C$2:$C$142,$A48,'Open General Opps CFY'!$I$2:$I$142,$B$4,'Open General Opps CFY'!$T$2:$T$142,1) -> 5 | F48: =IF(B48=0,0,E48/B48) -> 0.26315789
A49: APJ | B49: =COUNTIFS('Open General Opps CFY'!$C$2:$C$142,$A49,'Open General Opps CFY'!$I$2:$I$142,$B$4) -> 8 | C49: =COUNTIFS('Open General Opps CFY'!$C$2:$C$142,$A49,'Open General Opps CFY'!$I$2:$I$142,$B$4,'Open General Opps CFY'!$S$2:$S$142,1) -> 0 | D49: =IF(B49=0,0,C49/B49) -> 0 | E49: =COUNTIFS('Open General Opps CFY'!$C$2:$C$142,$A49,'Open General Opps CFY'!$I$2:$I$142,$B$4,'Open General Opps CFY'!$T$2:$T$142,1) -> 0 | F49: =IF(B49=0,0,E49/B49) -> 0
...

Sheet Open General Opps CFY
A1: Opportunity ID | B1: Office | C1: SAP Region | D1: Account Name | E1: Opportunity Owner | F1: Stage | G1: Executive Forecast Category | H1: Close Date | I1: Fiscal Period | J1: SAP Paper | K1: Forecast Tech MRR (EUR) | L1: BP ID | M1: Billing Address Line 1 | N1: Billing State/Province | O1: Billing Country | P1: Unassigned forecast | Q1: Missing tech MRR | R1: SAP Paper missing MRR | S1: Missing address | T1: Missing address and BP ID | U1: Past close date
A2: 006SYNQ30000075 | B2: UK | C2: =VLOOKUP(B2,'Lookup Data'!$A$4:$B$20,2,FALSE()) -> EMEA N | D2: Nimbus Beauty | E2: Owner EME04 | F2: Commercial Agreement | G2: - | H2: 45897 | I2: Q3-2025 | J2: =FALSE() -> FALSE | K2: 4840 | L2: 16407856 | M2: 174 Station Way | N2: West | O2: United Kingdom | P2: =IF(G2="-",1,0) -> 1 | Q2: =IF(N(K2)=0,1,0) -> 0 | R2: =IF(AND(J2=TRUE(),N(K2)=0),1,0) -> 0 | S2: =IF(OR(ISBLANK(M2),ISBLANK(N2),ISBLANK(O2)),1,0) -> 0 | T2: =IF(AND(S2=1,OR(ISBLANK(L2),L2="-")),1,0) -> 0 | U2: =IF(H2<ReportDate,1,0) -> 0
A3: 006SYNQ30000077 | B3: UK | C3: =VLOOKUP(B3,'Lookup Data'!$A$4:$B$20,2,FALSE()) -> EMEA N | D3: Arlo Living | E3: Owner EME04 | F3: Solution Presentation | G3: 3 - Best Case | H3: 45927 | I3: Q3-2025 | J3: =FALSE() -> FALSE | K3: 1640 | L3: 17484886 | M3: 129 Station Way | N3: West | O3: United Kingdom | P3: =IF(G3="-",1,0) -> 0 | Q3: =IF(N(K3)=0,1,0) -> 0 | R3: =IF(AND(J3=TRUE(),N(K3)=0),1,0) -> 0 | S3: =IF(OR(ISBLANK(M3),ISBLANK(N3),ISBLANK(O3)),1,0) -> 0 | T3: =IF(AND(S3=1,OR(ISBLANK(L3),L3="-")),1,0) -> 0 | U3: =IF(H3<ReportDate,1,0) -> 0
A4: 006SYNQ30000010 | B4: CA | C4: =VLOOKUP(B4,'Lookup Data'!$A$4:$B$20,2,FALSE()) -> NA | D4: Jasper Travel | E4: Owner NA06 | F4: Business chemistry & Scoping | G4: 3 - Best Case | H4: 45839 | I4: Q4-2025 | J4: =TRUE() -> TRUE | K4: 20390 | L4: 16694617 | M4: 143 Station Way | N4: South | O4: United States | P4: =IF(G4="-",1,0) -> 0 | Q4: =IF(N(K4)=0,1,0) -> 0 | R4: =IF(AND(J4=TRUE(),N(K4)=0),1,0) -> 0 | S4: =IF(OR(ISBLANK(M4),ISBLANK(N4),ISBLANK(O4)),1,0) -> 0 | T4: =IF(AND(S4=1,OR(ISBLANK(L4),L4="-")),1,0) -> 0 | U4: =IF(H4<ReportDate,1,0) -> 1
A5: 006SYNQ30000024 | B5: US | C5: =VLOOKUP(B5,'Lookup Data'!$A$4:$B$20,2,FALSE()) -> NA | D5: Lumen Living | E5: Owner NA02 | F5: Solution Presentation | G5: 3 - Best Case | H5: 45863 | I5: Q3-2025 | J5: =TRUE() -> TRUE | K5: 7280 | L5: 12684724 | M5: 215 Station Way | N5: Central | O5: United States | P5: =IF(G5="-",1,0) -> 0 | Q5: =IF(N(K5)=0,1,0) -> 0 | R5: =IF(AND(J5=TRUE(),N(K5)=0),1,0) -> 0 | S5: =IF(OR(ISBLANK(M5),ISBLANK(N5),ISBLANK(O5)),1,0) -> 0 | T5: =IF(AND(S5=1,OR(ISBLANK(L5),L5="-")),1,0) -> 0 | U5: =IF(H5<ReportDate,1,0) -> 0
A6: 006SYNQ30000076 | B6: NL | C6: =VLOOKUP(B6,'Lookup Data'!$A$4:$B$20,2,FALSE()) -> EMEA N | D6: Jasper Living | E6: Owner EME01 | F6: Contracting | G6: 3 - Best Case | H6: 45913 | I6: Q3-2025 | J6: =FALSE() -> FALSE | K6: 6860 | L6: 13646339 | M6: 47 Station Way | N6: Central | O6: United Kingdom | P6: =IF(G6="-",1,0) -> 0 | Q6: =IF(N(K6)=0,1,0) -> 0 | R6: =IF(AND(J6=TRUE(),N(K6)=0),1,0) -> 0 | S6: =IF(OR(ISBLANK(M6),ISBLANK(N6),ISBLANK(O6)),1,0) -> 0 | T6: =IF(AND(S6=1,OR(ISBLANK(L6),L6="-")),1,0) -> 0 | U6: =IF(H6<ReportDate,1,0) -> 0
A7: 006SYNQ30000015 | B7: US | C7: =VLOOKUP(B7,'Lookup Data'!$A$4:$B$20,2,FALSE()) -> NA | D7: Delmar Living | E7: Owner NA03 | F7: Business chemistry & Scoping | G7: 4 - Pipeline | H7: 45991 | I7: Q4-2025 | J7: =TRUE() -> TRUE | K7: 24720 | L7: 12238451 | O7: United States | P7: =IF(G7="-",1,0) -> 0 | Q7: =IF(N(K7)=0,1,0) -> 0 | R7: =IF(AND(J7=TRUE(),N(K7)=0),1,0) -> 0 | S7: =IF(OR(ISBLANK(M7),ISBLANK(N7),ISBLANK(O7)),1,0) -> 1 | T7: =IF(AND(S7=1,OR(ISBLANK(L7),L7="-")),1,0) -> 0 | U7: =IF(H7<ReportDate,1,0) -> 0
A8: 006SYNQ30000108 | B8: PL | C8: =VLOOKUP(B8,'Lookup Data'!$A$4:$B$20,2,FALSE()) -> MEE | D8: Garnet Travel | E8: Owner MEE01 | F8: Business chemistry & Scoping | G8: - | H8: 45840 | I8: Q4-2025 | J8: =TRUE() -> TRUE | K8: 6710 | L8: 17778845 | M8: 105 High Street | N8: Central | O8: Germany | P8: =IF(G8="-",1,0) -> 1 | Q8: =IF(N(K8)=0,1,0) -> 0 | R8: =IF(AND(J8=TRUE(),N(K8)=0),1,0) -> 0 | S8: =IF(OR(ISBLANK(M8),ISBLANK(N8),ISBLANK(O8)),1,0) -> 0 | T8: =IF(AND(S8=1,OR(ISBLANK(L8),L8="-")),1,0) -> 0 | U8: =IF(H8<ReportDate,1,0) -> 1
A9: 006SYNQ30000072 | B9: UK | C9: =VLOOKUP(B9,'Lookup Data'!$A$4:$B$20,2,FALSE()) -> EMEA N | D9: Summit Sports | E9: Owner EME04 | F9: Business chemistry & Scoping | G9: 4 - Pipeline | H9: 45913 | I9: Q3-2025 | J9: =TRUE() -> TRUE | K9: 15070 | L9: 14500849 | M9: 75 Station Way | N9: West | O9: United Kingdom | P9: =IF(G9="-",1,0) -> 0 | Q9: =IF(N(K9)=0,1,0) -> 0 | R9: =IF(AND(J9=TRUE(),N(K9)=0),1,0) -> 0 | S9: =IF(OR(ISBLANK(M9),ISBLANK(N9),ISBLANK(O9)),1,0) -> 0 | T9: =IF(AND(S9=1,OR(ISBLANK(L9),L9="-")),1,0) -> 0 | U9: =IF(H9<ReportDate,1,0) -> 0
A10: 006SYNQ30000023 | B10: US | C10: =VLOOKUP(B10,'Lookup Data'!$A$4:$B$20,2,FALSE()) -> NA | D10: Nimbus Retail | E10: Owner NA06 | F10: Business chemistry & Scoping | G10: 4 - Pipeline | H10: 45883 | I10: Q3-2025 | J10: =FALSE() -> FALSE | K10: 5440 | L10: 17042761 | M10: 193 Station Way | N10: West | O10: United States | P10: =IF(G10="-",1,0) -> 0 | Q10: =IF(N(K10)=0,1,0) -> 0 | R10: =IF(AND(J10=TRUE(),N(K10)=0),1,0) -> 0 | S10: =IF(OR(ISBLANK(M10),ISBLANK(N10),ISBLANK(O10)),1,0) -> 0 | T10: =IF(AND(S10=1,OR(ISBLANK(L10),L10="-")),1,0) -> 0 | U10: =IF(H10<ReportDate,1,0) -> 0
A11: 006SYNQ30000035 | B11: MX | C11: =VLOOKUP(B11,'Lookup Data'!$A$4:$B$20,2,FALSE()) -> LATAM | D11: Lumen Brands | E11: Owner LAT03 | F11: Commercial Agreement | G11: 4 - Pipeline | H11: 45890 | I11: Q3-2025 | J11: =FALSE() -> FALSE | K11: 9680 | L11: 14526000 | O11: Brazil | P11: =IF(G11="-",1,0) -> 0 | Q11: =IF(N(K11)=0,1,0) -> 0 | R11: =IF(AND(J11=TRUE(),N(K11)=0),1,0) -> 0 | S11: =IF(OR(ISBLANK(M11),ISBLANK(N11),ISBLANK(O11)),1,0) -> 1 | T11: =IF(AND(S11=1,OR(ISBLANK(L11),L11="-")),1,0) -> 0 | U11: =IF(H11<ReportDate,1,0) -> 0
A12: 006SYNQ30000089 | B12: ES | C12: =VLOOKUP(B12,'Lookup Data'!$A$4:$B$20,2,FALSE()) -> EMEA S | D12: Verity Travel | E12: Owner EME05 | F12: Business chemistry & Scoping | G12: 4 - Pipeline | H12: 45871 | I12: Q3-2025 | J12: =FALSE() -> FALSE | K12: 23850 | L12: 11375241 | M12: 173 Park Avenue | N12: South | O12: France | P12: =IF(G12="-",1,0) -> 0 | Q12: =IF(N(K12)=0,1,0) -> 0 | R12: =IF(AND(J12=TRUE(),N(K12)=0),1,0) -> 0 | S12: =IF(OR(ISBLANK(M12),ISBLANK(N12),ISBLANK(O12)),1,0) -> 0 | T12: =IF(AND(S12=1,OR(ISBLANK(L12),L12="-")),1,0) -> 0 | U12: =IF(H12<ReportDate,1,0) -> 0
A13: 006SYNQ30000140 | B13: HK | C13: =VLOOKUP(B13,'Lookup Data'!$A$4:$B$20,2,FALSE()) -> GCN | D13: Cobalt Travel | E13: Owner GCN02 | F13: Tech Agreement | G13: - | H13: 45987 | I13: Q4-2025 | J13: =FALSE() -> FALSE | K13: 19560 | L13: - | O13: Hong Kong | P13: =IF(G13="-",1,0) -> 1 | Q13: =IF(N(K13)=0,1,0) -> 0 | R13: =IF(AND(J13=TRUE(),N(K13)=0),1,0) -> 0 | S13: =IF(OR(ISBLANK(M13),ISBLANK(N13),ISBLANK(O13)),1,0) -> 1 | T13: =IF(AND(S13=1,OR(ISBLANK(L13),L13="-")),1,0) -> 1 | U13: =IF(H13<ReportDate,1,0) -> 0
A14: 006SYNQ30000118 | B14: AT | C14: =VLOOKUP(B14,'Lookup Data'!$A$4:$B$20,2,FALSE()) -> MEE | D14: Iris Living | E14: Owner MEE02 | F14: Business chemistry & Scoping | G14: 3 - Best Case | H14: 45882 | I14: Q3-2025 | J14: =TRUE() -> TRUE | K14: 11020 | L14: 13484610 | N14: South | O14: Germany | P14: =IF(G14="-",1,0) -> 0 | Q14: =IF(N(K14)=0,1,0) -> 0 | R14: =IF(AND(J14=TRUE(),N(K14)=0),1,0) -> 0 | S14: =IF(OR(ISBLANK(M14),ISBLANK(N14),ISBLANK(O14)),1,0) -> 1 | T14: =IF(AND(S14=1,OR(ISBLANK(L14),L14="-")),1,0) -> 0 | U14: =IF(H14<ReportDate,1,0) -> 0
A15: 006SYNQ30000041 | B15: MX | C15: =VLOOKUP(B15,'Lookup Data'!$A$4:$B$20,2,FALSE()) -> LATAM | D15: Tidal Telecom | E15: Owner LAT03 | F15: Business chemistry & Scoping | G15: - | H15: 45876 | I15: Q3-2025 | J15: =TRUE() -> TRUE | K15: 4830 | L15: 13923838 | M15: 65 Market Road | N15: Central | O15: Brazil | P15: =IF(G15="-",1,0) -> 1 | Q15: =IF(N(K15)=0,1,0) -> 0 | R15: =IF(AND(J15=TRUE(),N(K15)=0),1,0) -> 0 | S15: =IF(OR(ISBLANK(M15),ISBLANK(N15),ISBLANK(O15)),1,0) -> 0 | T15: =IF(AND(S15=1,OR(ISBLANK(L15),L15="-")),1,0) -> 0 | U15: =IF(H15<ReportDate,1,0) -> 0
A16: 006SYNQ30000045 | B16: UK | C16: =VLOOKUP(B16,'Lookup Data'!$A$4:$B$20,2,FALSE()) -> EMEA N | D16: Harbor Sports | E16: Owner EME03 | F16: Business chemistry & Scoping | G16: 3 - Best Case | H16: 45908 | I16: Q3-2025 | J16: =FALSE() -> FALSE | K16: 13620 | L16: 18174262 | M16: 177 Market Road | N16: North | O16: United Kingdom | P16: =IF(G16="-",1,0) -> 0 | Q16: =IF(N(K16)=0,1,0) -> 0 | R16: =IF(AND(J16=TRUE(),N(K16)=0),1,0) -> 0 | S16: =IF(OR(ISBLANK(M16),ISBLANK(N16),ISBLANK(O16)),1,0) -> 0 | T16: =IF(AND(S16=1,OR(ISBLANK(L16),L16="-")),1,0) -> 0 | U16: =IF(H16<ReportDate,1,0) -> 0
A17: 006SYNQ30000119 | B17: AT | C17: =VLOOKUP(B17,'Lookup Data'!$A$4:$B$20,2,FALSE()) -> MEE | D17: Jasper Foods | E17: Owner MEE01 | F17: Solution Presentation | G17: 3 - Best Case | H17: 45918 | I17: Q3-2025 | J17: =FALSE() -> FALSE | K17: 9500 | L17: 11907376 | M17: 60 High Street | N17: Central | O17: Germany | P17: =IF(G17="-",1,0) -> 0 | Q17: =IF(N(K17)=0,1,0) -> 0 | R17: =IF(AND(J17=TRUE(),N(K17)=0),1,0) -> 0 | S17: =IF(OR(ISBLANK(M17),ISBLANK(N17),ISBLANK(O17)),1,0) -> 0 | T17: =IF(AND(S17=1,OR(ISBLANK(L17),L17="-")),1,0) -> 0 | U17: =IF(H17<ReportDate,1,0) -> 0
A18: 006SYNQ30000112 | B18: DE | C18: =VLOOKUP(B18,'Lookup Data'!$A$4:$B$20,2,FALSE()) -> MEE | D18: Moreland Retail | E18: Owner MEE02 | F18: Solution Presentation | G18: - | H18: 45975 | I18: Q4-2025 | J18: =TRUE() -> TRUE | K18: 18790 | L18: 13947016 | M18: 164 Park Avenue | N18: North | O18: Germany | P18: =IF(G18="-",1,0) -> 1 | Q18: =IF(N(K18)=0,1,0) -> 0 | R18: =IF(AND(J18=TRUE(),N(K18)=0),1,0) -> 0 | S18: =IF(OR(ISBLANK(M18),ISBLANK(N18),ISBLANK(O18)),1,0) -> 0 | T18: =IF(AND(S18=1,OR(ISBLANK(L18),L18="-")),1,0) -> 0 | U18: =IF(H18<ReportDate,1,0) -> 0
A19: 006SYNQ30000034 | B19: MX | C19: =VLOOKUP(B19,'Lookup Data'!$A$4:$B$20,2,FALSE()) -> LATAM | D19: Lumen Outfitters | E19: Owner LAT01 | F19: Business chemistry & Scoping | G19: 4 - Pipeline | H19: 45860 | I19: Q3-2025 | J19: =TRUE() -> TRUE | K19: 24220 | L19: - | O19: Brazil | P19: =IF(G19="-",1,0) -> 0 | Q19: =IF(N(K19)=0,1,0) -> 0 | R19: =IF(AND(J19=TRUE(),N(K19)=0),1,0) -> 0 | S19: =IF(OR(ISBLANK(M19),ISBLANK(N19),ISBLANK(O19)),1,0) -> 1 | T19: =IF(AND(S19=1,OR(ISBLANK(L19),L19="-")),1,0) -> 1 | U19: =IF(H19<ReportDate,1,0) -> 0
A20: 006SYNQ30000032 | B20: MX | C20: =VLOOKUP(B20,'Lookup Data'!$A$4:$B$20,2,FALSE()) -> LATAM | D20: Osprey Telecom | E20: Owner LAT01 | F20: Commercial Agreement | G20: - | H20: 45890 | I20: Q3-2025 | J20: =TRUE() -> TRUE | K20: 11320 | L20: 15864098 | O20: Brazil | P20: =IF(G20="-",1,0) -> 1 | Q20: =IF(N(K20)=0,1,0) -> 0 | R20: =IF(AND(J20=TRUE(),N(K20)=0),1,0) -> 0 | S20: =IF(OR(ISBLANK(M20),ISBLANK(N20),ISBLANK(O20)),1,0) -> 1 | T20: =IF(AND(S20=1,OR(ISBLANK(L20),L20="-")),1,0) -> 0 | U20: =IF(H20<ReportDate,1,0) -> 0
A21: 006SYNQ30000131 | B21: HK | C21: =VLOOKUP(B21,'Lookup Data'!$A$4:$B$20,2,FALSE()) -> GCN | D21: Falcon Living | E21: Owner GCN04 | F21: Business chemistry & Scoping | G21: 4 - Pipeline | H21: 45851 | I21: Q3-2025 | J21: =FALSE() -> FALSE | K21: 11800 | L21: 17520742 | N21: North | O21: Hong Kong | P21: =IF(G21="-",1,0) -> 0 | Q21: =IF(N(K21)=0,1,0) -> 0 | R21: =IF(AND(J21=TRUE(),N(K21)=0),1,0) -> 0 | S21: =IF(OR(ISBLANK(M21),ISBLANK(N21),ISBLANK(O21)),1,0) -> 1 | T21: =IF(AND(S21=1,OR(ISBLANK(L21),L21="-")),1,0) -> 0 | U21: =IF(H21<ReportDate,1,0) -> 0
A22: 006SYNQ30000022 | B22: CA | C22: =VLOOKUP(B22,'Lookup Data'!$A$4:$B$20,2,FALSE()) -> NA | D22: Upton Brands | E22: Owner NA02 | F22: Tech Agreement | G22: 4 - Pipeline | H22: 45862 | I22: Q3-2025 | J22: =FALSE() -> FALSE | K22: 24250 | L22: 18606158 | M22: 111 Market Road | N22: West | O22: United States | P22: =IF(G22="-",1,0) -> 0 | Q22: =IF(N(K22)=0,1,0) -> 0 | R22: =IF(AND(J22=TRUE(),N(K22)=0),1,0) -> 0 | S22: =IF(OR(ISBLANK(M22),ISBLANK(N22),ISBLANK(O22)),1,0) -> 0 | T22: =IF(AND(S22=1,OR(ISBLANK(L22),L22="-")),1,0) -> 0 | U22: =IF(H22<ReportDate,1,0) -> 0
A23: 006SYNQ30000094 | B23: AT | C23: =VLOOKUP(B23,'Lookup Data'!$A$4:$B$20,2,FALSE()) -> MEE | D23: Moreland Beauty | E23: Owner MEE01 | F23: Commercial Agreement | G23: 3 - Best Case | H23: 45981 | I23: Q4-2025 | J23: =TRUE() -> TRUE | K23: 0 | L23: 11421983 | M23: 212 High Street | N23: South | O23: Germany | P23: =IF(G23="-",1,0) -> 0 | Q23: =IF(N(K23)=0,1,0) -> 1 | R23: =IF(AND(J23=TRUE(),N(K23)=0),1,0) -> 1 | S23: =IF(OR(ISBLANK(M23),ISBLANK(N23),ISBLANK(O23)),1,0) -> 0 | T23: =IF(AND(S23=1,OR(ISBLANK(L23),L23="-")),1,0) -> 0 | U23: =IF(H23<ReportDate,1,0) -> 0
A24: 006SYNQ30000078 | B24: NL | C24: =VLOOKUP(B24,'Lookup Data'!$A$4:$B$20,2,FALSE()) -> EMEA N | D24: Osprey Outfitters | E24: Owner EME04 | F24: Business chemistry & Scoping | G24: 4 - Pipeline | H24: 45920 | I24: Q3-2025 | J24: =FALSE() -> FALSE | K24: 0 | L24: 11098883 | M24: 59 Station Way | N24: Central | O24: United Kingdom | P24: =IF(G24="-",1,0) -> 0 | Q24: =IF(N(K24)=0,1,0) -> 1 | R24: =IF(AND(J24=TRUE(),N(K24)=0),1,0) -> 0 | S24: =IF(OR(ISBLANK(M24),ISBLANK(N24),ISBLANK(O24)),1,0) -> 0 | T24: =IF(AND(S24=1,OR(ISBLANK(L24),L24="-")),1,0) -> 0 | U24: =IF(H24<ReportDate,1,0) -> 0
A25: 006SYNQ30000005 | B25: US | C25: =VLOOKUP(B25,'Lookup Data'!$A$4:$B$20,2,FALSE()) -> NA | D25: Quarry Beauty | E25: Owner NA03 | F25: Solution Presentation | G25: 4 - Pipeline | H25: 45882 | I25: Q3-2025 | J25: =FALSE() -> FALSE | K25: 810 | L25: 19624313 | M25: 105 High Street | N25: Central | O25: United States | P25: =IF(G25="-",1,0) -> 0 | Q25: =IF(N(K25)=0,1,0) -> 0 | R25: =IF(AND(J25=TRUE(),N(K25)=0),1,0) -> 0 | S25: =IF(OR(ISBLANK(M25),ISBLANK(N25),ISBLANK(O25)),1,0) -> 0 | T25: =IF(AND(S25=1,OR(ISBLANK(L25),L25="-")),1,0) -> 0 | U25: =IF(H25<ReportDate,1,0) -> 0
A26: 006SYNQ30000129 | B26: AU | C26: =VLOOKUP(B26,'Lookup Data'!$A$4:$B$20,2,FALSE()) -> APJ | D26: Jasper Travel | E26: Owner APJ01 | F26: Commercial Agreement | G26: 3 - Best Case | H26: 45890 | I26: Q3-2025 | J26: =TRUE() -> TRUE | K26: 16300 | L26: 18383212 | M26: 99 Market Road | N26: Central | O26: Australia | P26: =IF(G26="-",1,0) -> 0 | Q26: =IF(N(K26)=0,1,0) -> 0 | R26: =IF(AND(J26=TRUE(),N(K26)=0),1,0) -> 0 | S26: =IF(OR(ISBLANK(M26),ISBLANK(N26),ISBLANK(O26)),1,0) -> 0 | T26: =IF(AND(S26=1,OR(ISBLANK(L26),L26="-")),1,0) -> 0 | U26: =IF(H26<ReportDate,1,0) -> 0
A27: 006SYNQ30000031 | B27: MX | C27: =VLOOKUP(B27,'Lookup Data'!$A$4:$B$20,2,FALSE()) -> LATAM | D27: Tidal Living | E27: Owner LAT05 | F27: Contracting | G27: 4 - Pipeline | H27: 45841 | I27: Q3-2025 | J27: =TRUE() -> TRUE | K27: 5670 | L27: - | O27: Brazil | P27: =IF(G27="-",1,0) -> 0 | Q27: =IF(N(K27)=0,1,0) -> 0 | R27: =IF(AND(J27=TRUE(),N(K27)=0),1,0) -> 0 | S27: =IF(OR(ISBLANK(M27),ISBLANK(N27),ISBLANK(O27)),1,0) -> 1 | T27: =IF(AND(S27=1,OR(ISBLANK(L27),L27="-")),1,0) -> 1 | U27: =IF(H27<ReportDate,1,0) -> 1
A28: 006SYNQ30000044 | B28: NL | C28: =VLOOKUP(B28,'Lookup Data'!$A$4:$B$20,2,FALSE()) -> EMEA N | D28: Delmar Telecom | E28: Owner EME04 | F28: Business chemistry & Scoping | G28: 4 - Pipeline | H28: 45924 | I28: Q3-2025 | J28: =TRUE() -> TRUE | K28: 18760 | L28: 12041310 | M28: 49 High Street | N28: Central | O28: United Kingdom | P28: =IF(G28="-",1,0) -> 0 | Q28: =IF(N(K28)=0,1,0) -> 0 | R28: =IF(AND(J28=TRUE(),N(K28)=0),1,0) -> 0 | S28: =IF(OR(ISBLANK(M28),ISBLANK(N28),ISBLANK(O28)),1,0) -> 0 | T28: =IF(AND(S28=1,OR(ISBLANK(L28),L28="-")),1,0) -> 0 | U28: =IF(H28<ReportDate,1,0) -> 0
A29: 006SYNQ30000080 | B29: FR | C29: =VLOOKUP(B29,'Lookup Data'!$A$4:$B$20,2,FALSE()) -> EMEA S | D29: Jasper Beauty | E29: Owner EME01 | F29: Solution Presentation | G29: - | H29: 45960 | I29: Q4-2025 | J29: =TRUE() -> TRUE | K29: 14880 | L29: 17581651 | M29: 140 Market Road | N29: West | O29: France | P29: =IF(G29="-",1,0) -> 1 | Q29: =IF(N(K29)=0,1,0) -> 0 | R29: =IF(AND(J29=TRUE(),N(K29)=0),1,0) -> 0 | S29: =IF(OR(ISBLANK(M29),ISBLANK(N29),ISBLANK(O29)),1,0) -> 0 | T29: =IF(AND(S29=1,OR(ISBLANK(L29),L29="-")),1,0) -> 0 | U29: =IF(H29<ReportDate,1,0) -> 0
A30: 006SYNQ30000042 | B30: MX | C30: =VLOOKUP(B30,'Lookup Data'!$A$4:$B$20,2,FALSE()) -> LATAM | D30: Osprey Brands | E30: Owner LAT03 | F30: Commercial Agreement | G30: 4 - Pipeline | H30: 45907 | I30: Q3-2025 | J30: =TRUE() -> TRUE | K30: 5060 | L30: 13773432 | N30: Central | O30: Brazil | P30: =IF(G30="-",1,0) -> 0 | Q30: =IF(N(K30)=0,1,0) -> 0 | R30: =IF(AND(J30=TRUE(),N(K30)=0),1,0) -> 0 | S30: =IF(OR(ISBLANK(M30),ISBLANK(N30),ISBLANK(O30)),1,0) -> 1 | T30: =IF(AND(S30=1,OR(ISBLANK(L30),L30="-")),1,0) -> 0 | U30: =IF(H30<ReportDate,1,0) -> 0
A31: 006SYNQ30000036 | B31: MX | C31: =VLOOKUP(B31,'Lookup Data'!$A$4:$B$20,2,FALSE()) -> LATAM | D31: Falcon Media | E31: Owner LAT06 | F31: Tech Agreement | G31: - | H31: 45859 | I31: Q3-2025 | J31: =FALSE() -> FALSE | K31: 17510 | L31: 18312894 | O31: Brazil | P31: =IF(G31="-",1,0) -> 1 | Q31: =IF(N(K31)=0,1,0) -> 0 | R31: =IF(AND(J31=TRUE(),N(K31)=0),1,0) -> 0 | S31: =IF(OR(ISBLANK(M31),ISBLANK(N31),ISBLANK(O31)),1,0) -> 1 | T31: =IF(AND(S31=1,OR(ISBLANK(L31),L31="-")),1,0) -> 0 | U31: =IF(H31<ReportDate,1,0) -> 0
A32: 006SYNQ30000114 | B32: AT | C32: =VLOOKUP(B32,'Lookup Data'!$A$4:$B$20,2,FALSE()) -> MEE | D32: Delmar Media | E32: Owner MEE05 | F32: Tech Agreement | G32: 3 - Best Case | H32: 45842 | I32: Q4-2025 | J32: =FALSE() -> FALSE | K32: 12100 | L32: 18493199 | N32: West | O32: Germany | P32: =IF(G32="-",1,0) -> 0 | Q32: =IF(N(K32)=0,1,0) -> 0 | R32: =IF(AND(J32=TRUE(),N(K32)=0),1,0) -> 0 | S32: =IF(OR(ISBLANK(M32),ISBLANK(N32),ISBLANK(O32)),1,0) -> 1 | T32: =IF(AND(S32=1,OR(ISBLANK(L32),L32="-")),1,0) -> 0 | U32: =IF(H32<ReportDate,1,0) -> 1
A33: 006SYNQ30000137 | B33: HK | C33: =VLOOKUP(B33,'Lookup Data'!$A$4:$B$20,2,FALSE()) -> GCN | D33: Lumen Sports | E33: Owner GCN01 | F33: Business chemistry & Scoping | G33: 4 - Pipeline | H33: 45918 | I33: Q3-2025 | J33: =TRUE() -> TRUE | K33: 0 | L33: 15160350 | O33: Hong Kong | P33: =IF(G33="-",1,0) -> 0 | Q33: =IF(N(K33)=0,1,0) -> 1 | R33: =IF(AND(J33=TRUE(),N(K33)=0),1,0) -> 1 | S33: =IF(OR(ISBLANK(M33),ISBLANK(N33),ISBLANK(O33)),1,0) -> 1 | T33: =IF(AND(S33=1,OR(ISBLANK(L33),L33="-")),1,0) -> 0 | U33: =IF(H33<ReportDate,1,0) -> 0
A34: 006SYNQ30000040 | B34: BR | C34: =VLOOKUP(B34,'Lookup Data'!$A$4:$B$20,2,FALSE()) -> LATAM | D34: Falcon Brands | E34: Owner LAT04 | F34: Contracting | G34: 3 - Best Case | H34: 45986 | I34: Q4-2025 | J34: =TRUE() -> TRUE | K34: 10180 | L34: - | O34: Brazil | P34: =IF(G34="-",1,0) -> 0 | Q34: =IF(N(K34)=0,1,0) -> 0 | R34: =IF(AND(J34=TRUE(),N(K34)=0),1,0) -> 0 | S34: =IF(OR(ISBLANK(M34),ISBLANK(N34),ISBLANK(O34)),1,0) -> 1 | T34: =IF(AND(S34=1,OR(ISBLANK(L34),L34="-")),1,0) -> 1 | U34: =IF(H34<ReportDate,1,0) -> 0
A35: 006SYNQ30000082 | B35: FR | C35: =VLOOKUP(B35,'Lookup Data'!$A$4:$B$20,2,FALSE()) -> EMEA S | D35: Falcon Telecom | E35: Owner EME03 | F35: Solution Presentation | G35: 1 - Commit | H35: 45881 | I35: Q3-2025 | J35: =FALSE() -> FALSE | K35: 24070 | L35: 11541289 | M35: 32 Station Way | N35: North | O35: France | P35: =IF(G35="-",1,0) -> 0 | Q35: =IF(N(K35)=0,1,0) -> 0 | R35: =IF(AND(J35=TRUE(),N(K35)=0),1,0) -> 0 | S35: =IF(OR(ISBLANK(M35),ISBLANK(N35),ISBLANK(O35)),1,0) -> 0 | T35: =IF(AND(S35=1,OR(ISBLANK(L35),L35="-")),1,0) -> 0 | U35: =IF(H35<ReportDate,1,0) -> 0
A36: 006SYNQ30000093 | B36: TR | C36: =VLOOKUP(B36,'Lookup Data'!$A$4:$B$20,2,FALSE()) -> EMEA S | D36: Osprey Travel | E36: Owner EME06 | F36: Solution Presentation | G36: 4 - Pipeline | H36: 45927 | I36: Q3-2025 | J36: =TRUE() -> TRUE | K36: 13660 | L36: 12519485 | M36: 63 Station Way | N36: West | O36: France | P36: =IF(G36="-",1,0) -> 0 | Q36: =IF(N(K36)=0,1,0) -> 0 | R36: =IF(AND(J36=TRUE(),N(K36)=0),1,0) -> 0 | S36: =IF(OR(ISBLANK(M36),ISBLANK(N36),ISBLANK(O36)),1,0) -> 0 | T36: =IF(AND(S36=1,OR(ISBLANK(L36),L36="-")),1,0) -> 0 | U36: =IF(H36<ReportDate,1,0) -> 0
A37: 006SYNQ30000001 | B37: US | C37: =VLOOKUP(B37,'Lookup Data'!$A$4:$B$20,2,FALSE()) -> NA | D37: Birch Brands | E37: Owner NA02 | F37: Contracting | G37: - | H37: 45908 | I37: Q3-2025 | J37: =FALSE() -> FALSE | K37: 9890 | L37: - | O37: United States | P37: =IF(G37="-",1,0) -> 1 | Q37: =IF(N(K37)=0,1,0) -> 0 | R37: =IF(AND(J37=TRUE(),N(K37)=0),1,0) -> 0 | S37: =IF(OR(ISBLANK(M37),ISBLANK(N37),ISBLANK(O37)),1,0) -> 1 | T37: =IF(AND(S37=1,OR(ISBLANK(L37),L37="-")),1,0) -> 1 | U37: =IF(H37<ReportDate,1,0) -> 0
A38: 006SYNQ30000128 | B38: SG | C38: =VLOOKUP(B38,'Lookup Data'!$A$4:$B$20,2,FALSE()) -> APJ | D38: Tidal Outfitters | E38: Owner APJ03 | F38: Business chemistry & Scoping | G38: 3 - Best Case | H38: 46012 | I38: Q4-2025 | J38: =FALSE() -> FALSE | K38: 12260 | L38: 10019228 | M38: 202 Station Way | N38: West | O38: Australia | P38: =IF(G38="-",1,0) -> 0 | Q38: =IF(N(K38)=0,1,0) -> 0 | R38: =IF(AND(J38=TRUE(),N(K38)=0),1,0) -> 0 | S38: =IF(OR(ISBLANK(M38),ISBLANK(N38),ISBLANK(O38)),1,0) -> 0 | T38: =IF(AND(S38=1,OR(ISBLANK(L38),L38="-")),1,0) -> 0 | U38: =IF(H38<ReportDate,1,0) -> 0
A39: 006SYNQ30000058 | B39: SE | C39: =VLOOKUP(B39,'Lookup Data'!$A$4:$B$20,2,FALSE()) -> EMEA N | D39: Kingsley Outfitters | E39: Owner EME06 | F39: Tech Agreement | G39: 4 - Pipeline | H39: 45860 | I39: Q3-2025 | J39: =TRUE() -> TRUE | K39: 1250 | L39: 17440395 | M39: 13 Park Avenue | N39: Central | O39: United Kingdom | P39: =IF(G39="-",1,0) -> 0 | Q39: =IF(N(K39)=0,1,0) -> 0 | R39: =IF(AND(J39=TRUE(),N(K39)=0),1,0) -> 0 | S39: =IF(OR(ISBLANK(M39),ISBLANK(N39),ISBLANK(O39)),1,0) -> 0 | T39: =IF(AND(S39=1,OR(ISBLANK(L39),L39="-")),1,0) -> 0 | U39: =IF(H39<ReportDate,1,0) -> 0
A40: 006SYNQ30000123 | B40: SG | C40: =VLOOKUP(B40,'Lookup Data'!$A$4:$B$20,2,FALSE()) -> APJ | D40: Ember Brands | E40: Owner APJ02 | F40: Business chemistry & Scoping | G40: 4 - Pipeline | H40: 45884 | I40: Q3-2025 | J40: =TRUE() -> TRUE | K40: 13600 | L40: 12634491 | M40: 213 Station Way | N40: South | O40: Australia | P40: =IF(G40="-",1,0) -> 0 | Q40: =IF(N(K40)=0,1,0) -> 0 | R40: =IF(AND(J40=TRUE(),N(K40)=0),1,0) -> 0 | S40: =IF(OR(ISBLANK(M40),ISBLANK(N40),ISBLANK(O40)),1,0) -> 0 | T40: =IF(AND(S40=1,OR(ISBLANK(L40),L40="-")),1,0) -> 0 | U40: =IF(H40<ReportDate,1,0) -> 0
...

Sheet Lookup Data
A1: Office to SAP Region
A3: Office | B3: SAP Region | D3: Quarter | F3: Report date
A4: US | B4: NA | D4: Q3-2025 | F4: 45846
A5: CA | B5: NA | D5: Q4-2025
A6: BR | B6: LATAM
A7: MX | B7: LATAM
A8: UK | B8: EMEA N
A9: SE | B9: EMEA N
A10: NL | B10: EMEA N
A11: FR | B11: EMEA S
A12: ES | B12: EMEA S
A13: TR | B13: EMEA S
A14: DE | B14: MEE
A15: AT | B15: MEE
A16: PL | B16: MEE
A17: AU | B17: APJ
... A20: CN | B20: GCN

Sheet Refresh Directions
A1: Refresh directions and handover
A2: Written so the next owner can run the file without me
A4: 1 | B4: Data > Refresh All to update the Salesforce queries and connections.
A5: 2 | B5: Unhide Open General Opps CFY and check the new extract has arrived.
A6: 3 | B6: On SFDC Admin Dashboard, choose the current quarter in B4.
A7: 4 | B7: Hide the extract again and check the dashboard for errors after every refresh, especially lookups.
A8: 5 | B8: In the close dates section, confirm every relevant month is covered.
A9: 6 | B9: Hide Summary Metrics workings and the raw extract before sending.
A10: 7 | B10: Maintenance: make sure no filter is left on the extract, validate the lookups after each refresh, and back the file up monthly with a date stamp.
