Workbook

Sheet README
B1: Pipeline Data Compliance: cleaned rebuild
B2: Cleaned file: real names, figures and records replaced with synthetic data of the same structure.
B4: What this file does
B6: Audits new business opportunity records so that account name, US SIC code and DUNS number agree between the CRM and D&B Hoovers, the trusted source. The original ran over 711 records, 693 accounts, 51 owners, 7 SAP regions and 9 fiscal quarters. This copy holds 150 synthetic audited records and a 60 row rolling pipeline extract with the same columns and the same logic.
B7: How it works
B9: • Rolling Pipeline: the refreshed Salesforce query (rolling four quarters). Each row looks itself up in the compliance table: if the Opportunity ID is not there yet it is flagged New and needs auditing.
B10: • Pipeline Compliance: the audited table. Every record is checked against D&B for name, SIC and DUNS, and its close date is checked against the report date. Each row ends in an issue count and a status.
B11: • Audit Summary: one row per SAP region with record, account and owner counts, every issue type, and the share of records that are clean. The global row is calculated from the totals.
B12: • Refresh Directions: the refresh and audit routine handed over with the file.
B13: Fixes made while cleaning (found in the original)
B15: • Days to close showed a broken reference error on every row of the compliance table; it now subtracts the report date from the close date.
B16: • The close date range formula referred to a row 37 rows below its own; it now reads its own row.
... B23: All account names, owners, IDs, DUNS numbers and values are invented. Region mix, stage mix and the share of records with issues were set to resemble the original so the summary behaves realistically.

Sheet Audit Summary
A1: Pipeline compliance audit by SAP region
A2: Counts from the Pipeline Compliance table. Global row is calculated from totals, not averaged.
A4: Report date | B4: 45855
A6: SAP Region | B6: Records | C6: Accounts | D6: Owners | E6: Name mismatch | F6: No D&B match | G6: SIC missing or wrong | H6: DUNS missing or wrong | I6: Past close date | J6: Clean records | K6: % clean | L6: New in rolling extract
A7: MEE | B7: =COUNTIF('Pipeline Compliance'!$D$2:$D$151,A7) -> 42 | C7: =SUMPRODUCT(('Pipeline Compliance'!$D$2:$D$151=A7)/COUNTIFS('Pipeline Compliance'!$A$2:$A$151,'Pipeline Compliance'!$A$2:$A$151,'Pipeline Compliance'!$D$2:$D$151,'Pipeline Compliance'!$D$2:$D$151)) -> 41 | D7: =SUMPRODUCT(('Pipeline Compliance'!$D$2:$D$151=A7)/COUNTIFS('Pipeline Compliance'!$F$2:$F$151,'Pipeline Compliance'!$F$2:$F$151,'Pipeline Compliance'!$D$2:$D$151,'Pipeline Compliance'!$D$2:$D$151)) -> 9 | E7: =COUNTIFS('Pipeline Compliance'!$D$2:$D$151,A7,'Pipeline Compliance'!$U$2:$U$151,"Mismatch") -> 7 | F7: =COUNTIFS('Pipeline Compliance'!$D$2:$D$151,A7,'Pipeline Compliance'!$U$2:$U$151,"No D&B match") -> 7 | G7: =COUNTIFS('Pipeline Compliance'!$D$2:$D$151,A7,'Pipeline Compliance'!$V$2:$V$151,"Mismatch")+COUNTIFS('Pipeline Compliance'!$D$2:$D$151,A7,'Pipeline Compliance'!$V$2:$V$151,"Missing in CRM") -> 5 | H7: =COUNTIFS('Pipeline Compliance'!$D$2:$D$151,A7,'Pipeline Compliance'!$W$2:$W$151,"Mismatch")+COUNTIFS('Pipeline Compliance'!$D$2:$D$151,A7,'Pipeline Compliance'!$W$2:$W$151,"Missing in CRM") -> 5 | I7: =COUNTIFS('Pipeline Compliance'!$D$2:$D$151,A7,'Pipeline Compliance'!$T$2:$T$151,"past closed") -> 27 | J7: =COUNTIFS('Pipeline Compliance'!$D$2:$D$151,A7,'Pipeline Compliance'!$Y$2:$Y$151,"Clean") -> 10 | K7: =IF(B7=0,0,J7/B7) -> 0.23809524 | L7: =COUNTIFS('Rolling Pipeline'!$D$2:$D$61,A7,'Rolling Pipeline'!$N$2:$N$61,"New") -> 5
A8: EMEA NORTH | B8: =COUNTIF('Pipeline Compliance'!$D$2:$D$151,A8) -> 31 | C8: =SUMPRODUCT(('Pipeline Compliance'!$D$2:$D$151=A8)/COUNTIFS('Pipeline Compliance'!$A$2:$A$151,'Pipeline Compliance'!$A$2:$A$151,'Pipeline Compliance'!$D$2:$D$151,'Pipeline Compliance'!$D$2:$D$151)) -> 30 | D8: =SUMPRODUCT(('Pipeline Compliance'!$D$2:$D$151=A8)/COUNTIFS('Pipeline Compliance'!$F$2:$F$151,'Pipeline Compliance'!$F$2:$F$151,'Pipeline Compliance'!$D$2:$D$151,'Pipeline Compliance'!$D$2:$D$151)) -> 7 | E8: =COUNTIFS('Pipeline Compliance'!$D$2:$D$151,A8,'Pipeline Compliance'!$U$2:$U$151,"Mismatch") -> 6 | F8: =COUNTIFS('Pipeline Compliance'!$D$2:$D$151,A8,'Pipeline Compliance'!$U$2:$U$151,"No D&B match") -> 2 | G8: =COUNTIFS('Pipeline Compliance'!$D$2:$D$151,A8,'Pipeline Compliance'!$V$2:$V$151,"Mismatch")+COUNTIFS('Pipeline Compliance'!$D$2:$D$151,A8,'Pipeline Compliance'!$V$2:$V$151,"Missing in CRM") -> 7 | H8: =COUNTIFS('Pipeline Compliance'!$D$2:$D$151,A8,'Pipeline Compliance'!$W$2:$W$151,"Mismatch")+COUNTIFS('Pipeline Compliance'!$D$2:$D$151,A8,'Pipeline Compliance'!$W$2:$W$151,"Missing in CRM") -> 7 | I8: =COUNTIFS('Pipeline Compliance'!$D$2:$D$151,A8,'Pipeline Compliance'!$T$2:$T$151,"past closed") -> 19 | J8: =COUNTIFS('Pipeline Compliance'!$D$2:$D$151,A8,'Pipeline Compliance'!$Y$2:$Y$151,"Clean") -> 6 | K8: =IF(B8=0,0,J8/B8) -> 0.19354839 | L8: =COUNTIFS('Rolling Pipeline'!$D$2:$D$61,A8,'Rolling Pipeline'!$N$2:$N$61,"New") -> 4
A9: EMEA SOUTH | B9: =COUNTIF('Pipeline Compliance'!$D$2:$D$151,A9) -> 32 | C9: =SUMPRODUCT(('Pipeline Compliance'!$D$2:$D$151=A9)/COUNTIFS('Pipeline Compliance'!$A$2:$A$151,'Pipeline Compliance'!$A$2:$A$151,'Pipeline Compliance'!$D$2:$D$151,'Pipeline Compliance'!$D$2:$D$151)) -> 30 | D9: =SUMPRODUCT(('Pipeline Compliance'!$D$2:$D$151=A9)/COUNTIFS('Pipeline Compliance'!$F$2:$F$151,'Pipeline Compliance'!$F$2:$F$151,'Pipeline Compliance'!$D$2:$D$151,'Pipeline Compliance'!$D$2:$D$151)) -> 6 | E9: =COUNTIFS('Pipeline Compliance'!$D$2:$D$151,A9,'Pipeline Compliance'!$U$2:$U$151,"Mismatch") -> 4 | F9: =COUNTIFS('Pipeline Compliance'!$D$2:$D$151,A9,'Pipeline Compliance'!$U$2:$U$151,"No D&B match") -> 2 | G9: =COUNTIFS('Pipeline Compliance'!$D$2:$D$151,A9,'Pipeline Compliance'!$V$2:$V$151,"Mismatch")+COUNTIFS('Pipeline Compliance'!$D$2:$D$151,A9,'Pipeline Compliance'!$V$2:$V$151,"Missing in CRM") -> 5 | H9: =COUNTIFS('Pipeline Compliance'!$D$2:$D$151,A9,'Pipeline Compliance'!$W$2:$W$151,"Mismatch")+COUNTIFS('Pipeline Compliance'!$D$2:$D$151,A9,'Pipeline Compliance'!$W$2:$W$151,"Missing in CRM") -> 6 | I9: =COUNTIFS('Pipeline Compliance'!$D$2:$D$151,A9,'Pipeline Compliance'!$T$2:$T$151,"past closed") -> 17 | J9: =COUNTIFS('Pipeline Compliance'!$D$2:$D$151,A9,'Pipeline Compliance'!$Y$2:$Y$151,"Clean") -> 12 | K9: =IF(B9=0,0,J9/B9) -> 0.375 | L9: =COUNTIFS('Rolling Pipeline'!$D$2:$D$61,A9,'Rolling Pipeline'!$N$2:$N$61,"New") -> 2
A10: NA | B10: =COUNTIF('Pipeline Compliance'!$D$2:$D$151,A10) -> 22 | C10: =SUMPRODUCT(('Pipeline Compliance'!$D$2:$D$151=A10)/COUNTIFS('Pipeline Compliance'!$A$2:$A$151,'Pipeline Compliance'!$A$2:$A$151,'Pipeline Compliance'!$D$2:$D$151,'Pipeline Compliance'!$D$2:$D$151)) -> 20 | D10: =SUMPRODUCT(('Pipeline Compliance'!$D$2:$D$151=A10)/COUNTIFS('Pipeline Compliance'!$F$2:$F$151,'Pipeline Compliance'!$F$2:$F$151,'Pipeline Compliance'!$D$2:$D$151,'Pipeline Compliance'!$D$2:$D$151)) -> 6 | E10: =COUNTIFS('Pipeline Compliance'!$D$2:$D$151,A10,'Pipeline Compliance'!$U$2:$U$151,"Mismatch") -> 2 | F10: =COUNTIFS('Pipeline Compliance'!$D$2:$D$151,A10,'Pipeline Compliance'!$U$2:$U$151,"No D&B match") -> 2 | G10: =COUNTIFS('Pipeline Compliance'!$D$2:$D$151,A10,'Pipeline Compliance'!$V$2:$V$151,"Mismatch")+COUNTIFS('Pipeline Compliance'!$D$2:$D$151,A10,'Pipeline Compliance'!$V$2:$V$151,"Missing in CRM") -> 5 | H10: =COUNTIFS('Pipeline Compliance'!$D$2:$D$151,A10,'Pipeline Compliance'!$W$2:$W$151,"Mismatch")+COUNTIFS('Pipeline Compliance'!$D$2:$D$151,A10,'Pipeline Compliance'!$W$2:$W$151,"Missing in CRM") -> 5 | I10: =COUNTIFS('Pipeline Compliance'!$D$2:$D$151,A10,'Pipeline Compliance'!$T$2:$T$151,"past closed") -> 14 | J10: =COUNTIFS('Pipeline Compliance'!$D$2:$D$151,A10,'Pipeline Compliance'!$Y$2:$Y$151,"Clean") -> 6 | K10: =IF(B10=0,0,J10/B10) -> 0.27272727 | L10: =COUNTIFS('Rolling Pipeline'!$D$2:$D$61,A10,'Rolling Pipeline'!$N$2:$N$61,"New") -> 4
A11: LATAM | B11: =COUNTIF('Pipeline Compliance'!$D$2:$D$151,A11) -> 10 | C11: =SUMPRODUCT(('Pipeline Compliance'!$D$2:$D$151=A11)/COUNTIFS('Pipeline Compliance'!$A$2:$A$151,'Pipeline Compliance'!$A$2:$A$151,'Pipeline Compliance'!$D$2:$D$151,'Pipeline Compliance'!$D$2:$D$151)) -> 10 | D11: =SUMPRODUCT(('Pipeline Compliance'!$D$2:$D$151=A11)/COUNTIFS('Pipeline Compliance'!$F$2:$F$151,'Pipeline Compliance'!$F$2:$F$151,'Pipeline Compliance'!$D$2:$D$151,'Pipeline Compliance'!$D$2:$D$151)) -> 4 | E11: =COUNTIFS('Pipeline Compliance'!$D$2:$D$151,A11,'Pipeline Compliance'!$U$2:$U$151,"Mismatch") -> 1 | F11: =COUNTIFS('Pipeline Compliance'!$D$2:$D$151,A11,'Pipeline Compliance'!$U$2:$U$151,"No D&B match") -> 2 | G11: =COUNTIFS('Pipeline Compliance'!$D$2:$D$151,A11,'Pipeline Compliance'!$V$2:$V$151,"Mismatch")+COUNTIFS('Pipeline Compliance'!$D$2:$D$151,A11,'Pipeline Compliance'!$V$2:$V$151,"Missing in CRM") -> 1 | H11: =COUNTIFS('Pipeline Compliance'!$D$2:$D$151,A11,'Pipeline Compliance'!$W$2:$W$151,"Mismatch")+COUNTIFS('Pipeline Compliance'!$D$2:$D$151,A11,'Pipeline Compliance'!$W$2:$W$151,"Missing in CRM") -> 2 | I11: =COUNTIFS('Pipeline Compliance'!$D$2:$D$151,A11,'Pipeline Compliance'!$T$2:$T$151,"past closed") -> 7 | J11: =COUNTIFS('Pipeline Compliance'!$D$2:$D$151,A11,'Pipeline Compliance'!$Y$2:$Y$151,"Clean") -> 2 | K11: =IF(B11=0,0,J11/B11) -> 0.2 | L11: =COUNTIFS('Rolling Pipeline'!$D$2:$D$61,A11,'Rolling Pipeline'!$N$2:$N$61,"New") -> 2
A12: GCN | B12: =COUNTIF('Pipeline Compliance'!$D$2:$D$151,A12) -> 7 | C12: =SUMPRODUCT(('Pipeline Compliance'!$D$2:$D$151=A12)/COUNTIFS('Pipeline Compliance'!$A$2:$A$151,'Pipeline Compliance'!$A$2:$A$151,'Pipeline Compliance'!$D$2:$D$151,'Pipeline Compliance'!$D$2:$D$151)) -> 7 | D12: =SUMPRODUCT(('Pipeline Compliance'!$D$2:$D$151=A12)/COUNTIFS('Pipeline Compliance'!$F$2:$F$151,'Pipeline Compliance'!$F$2:$F$151,'Pipeline Compliance'!$D$2:$D$151,'Pipeline Compliance'!$D$2:$D$151)) -> 2 | E12: =COUNTIFS('Pipeline Compliance'!$D$2:$D$151,A12,'Pipeline Compliance'!$U$2:$U$151,"Mismatch") -> 0 | F12: =COUNTIFS('Pipeline Compliance'!$D$2:$D$151,A12,'Pipeline Compliance'!$U$2:$U$151,"No D&B match") -> 2 | G12: =COUNTIFS('Pipeline Compliance'!$D$2:$D$151,A12,'Pipeline Compliance'!$V$2:$V$151,"Mismatch")+COUNTIFS('Pipeline Compliance'!$D$2:$D$151,A12,'Pipeline Compliance'!$V$2:$V$151,"Missing in CRM") -> 1 | H12: =COUNTIFS('Pipeline Compliance'!$D$2:$D$151,A12,'Pipeline Compliance'!$W$2:$W$151,"Mismatch")+COUNTIFS('Pipeline Compliance'!$D$2:$D$151,A12,'Pipeline Compliance'!$W$2:$W$151,"Missing in CRM") -> 1 | I12: =COUNTIFS('Pipeline Compliance'!$D$2:$D$151,A12,'Pipeline Compliance'!$T$2:$T$151,"past closed") -> 5 | J12: =COUNTIFS('Pipeline Compliance'!$D$2:$D$151,A12,'Pipeline Compliance'!$Y$2:$Y$151,"Clean") -> 1 | K12: =IF(B12=0,0,J12/B12) -> 0.14285714 | L12: =COUNTIFS('Rolling Pipeline'!$D$2:$D$61,A12,'Rolling Pipeline'!$N$2:$N$61,"New") -> 0
A13: APJ | B13: =COUNTIF('Pipeline Compliance'!$D$2:$D$151,A13) -> 6 | C13: =SUMPRODUCT(('Pipeline Compliance'!$D$2:$D$151=A13)/COUNTIFS('Pipeline Compliance'!$A$2:$A$151,'Pipeline Compliance'!$A$2:$A$151,'Pipeline Compliance'!$D$2:$D$151,'Pipeline Compliance'!$D$2:$D$151)) -> 6 | D13: =SUMPRODUCT(('Pipeline Compliance'!$D$2:$D$151=A13)/COUNTIFS('Pipeline Compliance'!$F$2:$F$151,'Pipeline Compliance'!$F$2:$F$151,'Pipeline Compliance'!$D$2:$D$151,'Pipeline Compliance'!$D$2:$D$151)) -> 2 | E13: =COUNTIFS('Pipeline Compliance'!$D$2:$D$151,A13,'Pipeline Compliance'!$U$2:$U$151,"Mismatch") -> 0 | F13: =COUNTIFS('Pipeline Compliance'!$D$2:$D$151,A13,'Pipeline Compliance'!$U$2:$U$151,"No D&B match") -> 1 | G13: =COUNTIFS('Pipeline Compliance'!$D$2:$D$151,A13,'Pipeline Compliance'!$V$2:$V$151,"Mismatch")+COUNTIFS('Pipeline Compliance'!$D$2:$D$151,A13,'Pipeline Compliance'!$V$2:$V$151,"Missing in CRM") -> 1 | H13: =COUNTIFS('Pipeline Compliance'!$D$2:$D$151,A13,'Pipeline Compliance'!$W$2:$W$151,"Mismatch")+COUNTIFS('Pipeline Compliance'!$D$2:$D$151,A13,'Pipeline Compliance'!$W$2:$W$151,"Missing in CRM") -> 1 | I13: =COUNTIFS('Pipeline Compliance'!$D$2:$D$151,A13,'Pipeline Compliance'!$T$2:$T$151,"past closed") -> 3 | J13: =COUNTIFS('Pipeline Compliance'!$D$2:$D$151,A13,'Pipeline Compliance'!$Y$2:$Y$151,"Clean") -> 2 | K13: =IF(B13=0,0,J13/B13) -> 0.33333333 | L13: =COUNTIFS('Rolling Pipeline'!$D$2:$D$61,A13,'Rolling Pipeline'!$N$2:$N$61,"New") -> 3
A14: Global | B14: =SUM(B7:B13) -> 150 | C14: =SUMPRODUCT(1/COUNTIF('Pipeline Compliance'!$A$2:$A$151,'Pipeline Compliance'!$A$2:$A$151)) -> 144 | D14: =SUMPRODUCT(1/COUNTIF('Pipeline Compliance'!$F$2:$F$151,'Pipeline Compliance'!$F$2:$F$151)) -> 36 | E14: =SUM(E7:E13) -> 20 | F14: =SUM(F7:F13) -> 18 | G14: =SUM(G7:G13) -> 25 | H14: =SUM(H7:H13) -> 27 | I14: =SUM(I7:I13) -> 92 | J14: =SUM(J7:J13) -> 39 | K14: =IF(B14=0,0,J14/B14) -> 0.26 | L14: =SUM(L7:L13) -> 20
A16: Accounts and owners are distinct counts (SUMPRODUCT over COUNTIFS), so an account with several opportunities is counted once.
A17: Synthetic data. The original audit covered 711 records, 693 accounts and 51 owners across these 7 regions.

Sheet Rolling Pipeline
A1: Account ID | B1: Opportunity ID | C1: Office | D1: SAP Region | E1: Opportunity Name | F1: Opportunity Owner | G1: Account Name | H1: Stage | I1: Created Date | J1: Close Date | K1: Fiscal Period | L1: ACV (EUR) | M1: Account Name (D&B lookup) | N1: New Opportunities | O1: Days to close | P1: Close date range
A2: 001SYN000131 | B2: 006SYN000000131 | C2: HK | D2: GCN | E2: 12/Core-Adv-Omni/156K/Quill | F2: Owner GC01 | G2: Quill Fashion Limited | H2: Solution presentation | I2: 45330 | J2: 45428 | K2: Q2-2024 | L2: 156200 | M2: =IFERROR(INDEX('Pipeline Compliance'!$H$2:$H$151,MATCH(B2,'Pipeline Compliance'!$B$2:$B$151,0)),"") -> Quill Fashion Limited | N2: =IF(ISNA(MATCH(B2,'Pipeline Compliance'!$B$2:$B$151,0)),"New","Old") -> Old | O2: =IF(H2="Closed Won","",J2-ReportDate) -> -427 | P2: =IF(H2="Closed Won","closed",IF(O2<0,"past closed",IF(O2<=10,"update","on track"))) -> past closed
A3: 001SYN000077 | B3: 006SYN000000077 | C3: US | D3: NA | E3: 36/Core+Ecom/21K/Marlow | F3: Owner NA02 | G3: Marlow Optics Inc. | H3: Commercial agreement | I3: 45800 | J3: 45957 | K3: Q4-2025 | L3: 21200 | M3: =IFERROR(INDEX('Pipeline Compliance'!$H$2:$H$151,MATCH(B3,'Pipeline Compliance'!$B$2:$B$151,0)),"") -> Marlow Optics Inc. | N3: =IF(ISNA(MATCH(B3,'Pipeline Compliance'!$B$2:$B$151,0)),"New","Old") -> Old | O3: =IF(H3="Closed Won","",J3-ReportDate) -> 102 | P3: =IF(H3="Closed Won","closed",IF(O3<0,"past closed",IF(O3<=10,"update","on track"))) -> on track
A4: 001SYN000026 | B4: 006SYN000000026 | C4: DE | D4: MEE | E4: 12/Essentials+Mob/268K/Carrow | F4: Owner ME07 | G4: Carrow Fashion GmbH | H4: Commercial agreement | I4: 45404 | J4: 45469 | K4: Q2-2024 | L4: 268800 | M4: =IFERROR(INDEX('Pipeline Compliance'!$H$2:$H$151,MATCH(B4,'Pipeline Compliance'!$B$2:$B$151,0)),"") -> Carrow Fashion GmbH | N4: =IF(ISNA(MATCH(B4,'Pipeline Compliance'!$B$2:$B$151,0)),"New","Old") -> Old | O4: =IF(H4="Closed Won","",J4-ReportDate) -> -386 | P4: =IF(H4="Closed Won","closed",IF(O4<0,"past closed",IF(O4<=10,"update","on track"))) -> past closed
A5: 001SYN001015 | B5: 006SYN000001015 | C5: AU | D5: APJ | E5: 12/Core+Omni/124K/Vesta | F5: Owner AP03 | G5: Vesta Fashion Pty Ltd | H5: Solution presentation | I5: 45660 | J5: 45743 | K5: Q1-2025 | L5: 124800 | M5: =IFERROR(INDEX('Pipeline Compliance'!$H$2:$H$151,MATCH(B5,'Pipeline Compliance'!$B$2:$B$151,0)),"") | N5: =IF(ISNA(MATCH(B5,'Pipeline Compliance'!$B$2:$B$151,0)),"New","Old") -> New | O5: =IF(H5="Closed Won","",J5-ReportDate) -> -112 | P5: =IF(H5="Closed Won","closed",IF(O5<0,"past closed",IF(O5<=10,"update","on track"))) -> past closed
A6: 001SYN001001 | B6: 006SYN000001001 | C6: BR | D6: LATAM | E6: 12/Core+Ecom/47K/Juniper | F6: Owner LA04 | G6: Juniper Home Ltda | H6: Solution presentation | I6: 45515 | J6: 45634 | K6: Q4-2024 | L6: 47500 | M6: =IFERROR(INDEX('Pipeline Compliance'!$H$2:$H$151,MATCH(B6,'Pipeline Compliance'!$B$2:$B$151,0)),"") | N6: =IF(ISNA(MATCH(B6,'Pipeline Compliance'!$B$2:$B$151,0)),"New","Old") -> New | O6: =IF(H6="Closed Won","",J6-ReportDate) -> -221 | P6: =IF(H6="Closed Won","closed",IF(O6<0,"past closed",IF(O6<=10,"update","on track"))) -> past closed
A7: 001SYN000033 | B7: 006SYN000000033 | C7: IT | D7: EMEA SOUTH | E7: 24/Core+Omni/171K/Calder | F7: Owner ES02 | G7: Calder Retail S.p.A. | H7: Closed Won | I7: 45330 | J7: 45559 | K7: Q3-2024 | L7: 171200 | M7: =IFERROR(INDEX('Pipeline Compliance'!$H$2:$H$151,MATCH(B7,'Pipeline Compliance'!$B$2:$B$151,0)),"") -> Calder Retail S.p.A. | N7: =IF(ISNA(MATCH(B7,'Pipeline Compliance'!$B$2:$B$151,0)),"New","Old") -> Old | O7: =IF(H7="Closed Won","",J7-ReportDate) | P7: =IF(H7="Closed Won","closed",IF(O7<0,"past closed",IF(O7<=10,"update","on track"))) -> closed
A8: 001SYN000105 | B8: 006SYN000000105 | C8: CH | D8: MEE | E8: 12/Essentials+Mob/83K/Tavish | F8: Owner ME02 | G8: Tavish Outdoor AG | H8: Business chemistry & scoping | I8: 45310 | J8: 45466 | K8: Q2-2024 | L8: 83600 | M8: =IFERROR(INDEX('Pipeline Compliance'!$H$2:$H$151,MATCH(B8,'Pipeline Compliance'!$B$2:$B$151,0)),"") -> Tavish Outdoor AG | N8: =IF(ISNA(MATCH(B8,'Pipeline Compliance'!$B$2:$B$151,0)),"New","Old") -> Old | O8: =IF(H8="Closed Won","",J8-ReportDate) -> -389 | P8: =IF(H8="Closed Won","closed",IF(O8<0,"past closed",IF(O8<=10,"update","on track"))) -> past closed
A9: 001SYN001012 | B9: 006SYN000001012 | C9: US | D9: NA | E9: 36/Essentials+Mob/191K/Tavish | F9: Owner NA03 | G9: Tavish Living Inc. | H9: Solution presentation | I9: 45708 | J9: 45854 | K9: Q3-2025 | L9: 191500 | M9: =IFERROR(INDEX('Pipeline Compliance'!$H$2:$H$151,MATCH(B9,'Pipeline Compliance'!$B$2:$B$151,0)),"") | N9: =IF(ISNA(MATCH(B9,'Pipeline Compliance'!$B$2:$B$151,0)),"New","Old") -> New | O9: =IF(H9="Closed Won","",J9-ReportDate) -> -1 | P9: =IF(H9="Closed Won","closed",IF(O9<0,"past closed",IF(O9<=10,"update","on track"))) -> past closed
A10: 001SYN001000 | B10: 006SYN000001000 | C10: IE | D10: EMEA NORTH | E10: 24/Core-Adv-Omni/52K/Larch | F10: Owner EN01 | G10: Larch Pharma Ltd | H10: Solution presentation | I10: 45432 | J10: 45627 | K10: Q4-2024 | L10: 52000 | M10: =IFERROR(INDEX('Pipeline Compliance'!$H$2:$H$151,MATCH(B10,'Pipeline Compliance'!$B$2:$B$151,0)),"") | N10: =IF(ISNA(MATCH(B10,'Pipeline Compliance'!$B$2:$B$151,0)),"New","Old") -> New | O10: =IF(H10="Closed Won","",J10-ReportDate) -> -228 | P10: =IF(H10="Closed Won","closed",IF(O10<0,"past closed",IF(O10<=10,"update","on track"))) -> past closed
A11: 001SYN000093 | B11: 006SYN000000093 | C11: AT | D11: MEE | E11: 36/Core+Ecom/412K/Brook | F11: Owner ME01 | G11: Brook Optics GmbH | H11: Business chemistry & scoping | I11: 45396 | J11: 45626 | K11: Q4-2024 | L11: 412000 | M11: =IFERROR(INDEX('Pipeline Compliance'!$H$2:$H$151,MATCH(B11,'Pipeline Compliance'!$B$2:$B$151,0)),"") -> Brook Optics GmbH | N11: =IF(ISNA(MATCH(B11,'Pipeline Compliance'!$B$2:$B$151,0)),"New","Old") -> Old | O11: =IF(H11="Closed Won","",J11-ReportDate) -> -229 | P11: =IF(H11="Closed Won","closed",IF(O11<0,"past closed",IF(O11<=10,"update","on track"))) -> past closed
A12: 001SYN001013 | B12: 006SYN000001013 | C12: US | D12: NA | E12: 12/Core-Adv-Omni/37K/Dunmore | F12: Owner NA06 | G12: Dunmore Media Inc. | H12: Solution presentation | I12: 45417 | J12: 45592 | K12: Q4-2024 | L12: 37000 | M12: =IFERROR(INDEX('Pipeline Compliance'!$H$2:$H$151,MATCH(B12,'Pipeline Compliance'!$B$2:$B$151,0)),"") | N12: =IF(ISNA(MATCH(B12,'Pipeline Compliance'!$B$2:$B$151,0)),"New","Old") -> New | O12: =IF(H12="Closed Won","",J12-ReportDate) -> -263 | P12: =IF(H12="Closed Won","closed",IF(O12<0,"past closed",IF(O12<=10,"update","on track"))) -> past closed
A13: 001SYN000065 | B13: 006SYN000000065 | C13: AT | D13: MEE | E13: 36/Core+Ecom+Omni/26K/Arden | F13: Owner ME04 | G13: Arden Motors GmbH | H13: Solution presentation | I13: 45551 | J13: 45629 | K13: Q4-2024 | L13: 26100 | M13: =IFERROR(INDEX('Pipeline Compliance'!$H$2:$H$151,MATCH(B13,'Pipeline Compliance'!$B$2:$B$151,0)),"") -> Arden Motors GmbH & Co. KG | N13: =IF(ISNA(MATCH(B13,'Pipeline Compliance'!$B$2:$B$151,0)),"New","Old") -> Old | O13: =IF(H13="Closed Won","",J13-ReportDate) -> -226 | P13: =IF(H13="Closed Won","closed",IF(O13<0,"past closed",IF(O13<=10,"update","on track"))) -> past closed
... A61: 001SYN001011 | B61: 006SYN000001011 | C61: NL | D61: EMEA NORTH | E61: 36/Core+Omni/487K/Arden | F61: Owner EN07 | G61: Arden Brands B.V. | H61: Business chemistry & scoping | I61: 45568 | J61: 45696 | K61: Q1-2025 | L61: 487400 | M61: =IFERROR(INDEX('Pipeline Compliance'!$H$2:$H$151,MATCH(B61,'Pipeline Compliance'!$B$2:$B$151,0)),"") | N61: =IF(ISNA(MATCH(B61,'Pipeline Compliance'!$B$2:$B$151,0)),"New","Old") -> New | O61: =IF(H61="Closed Won","",J61-ReportDate) -> -159 | P61: =IF(H61="Closed Won","closed",IF(O61<0,"past closed",IF(O61<=10,"update","on track"))) -> past closed

Sheet Pipeline Compliance
A1: Account ID | B1: Opportunity ID | C1: Office | D1: SAP Region | E1: Opportunity Name | F1: Opportunity Owner | G1: Account Name (CRM) | H1: Account Name (D&B) | I1: Industry | J1: US SIC4 (CRM) | K1: US SIC4 (D&B) | L1: DUNS (CRM) | M1: DUNS (D&B) | N1: Stage | O1: Created Date | P1: Close Date | Q1: Fiscal Period | R1: ACV (EUR) | S1: Days to close | T1: Close date range | U1: Name check | V1: SIC check | W1: DUNS check | X1: Issues | Y1: Audit status
A2: 001SYN000001 | B2: 006SYN000000001 | C2: TR | D2: EMEA SOUTH | E2: 12/Core+Ecom/156K/Holloway | F2: Owner ES06 | G2: Holloway Travel A.S. | H2: Holloway Travel A.S. | I2: Media | J2: 4841 | K2: 4841 | L2: 343350125 | M2: 343350125 | N2: Commercial agreement | O2: 45544 | P2: 45702 | Q2: Q1-2025 | R2: 156200 | S2: =IF(N2="Closed Won","",P2-ReportDate) -> -153 | T2: =IF(N2="Closed Won","closed",IF(S2<0,"past closed",IF(S2<=10,"update","on track"))) -> past closed | U2: =IF(H2="","No D&B match",IF(TRIM(G2)=TRIM(H2),"Match","Mismatch")) -> Match | V2: =IF(K2="","No D&B match",IF(J2="","Missing in CRM",IF(J2=K2,"Match","Mismatch"))) -> Match | W2: =IF(M2="","No D&B match",IF(L2="","Missing in CRM",IF(L2=M2,"Match","Mismatch"))) -> Match | X2: =COUNTIF(U2:W2,"<>Match")+IF(T2="past closed",1,0) -> 1 | Y2: =IF(X2=0,"Clean","Review") -> Review
A3: 001SYN000002 | B3: 006SYN000000002 | C3: DE | D3: MEE | E3: 24/Core+Loyalty/78K/Calder | F3: Owner ME08 | G3: Calder Travel GmbH | H3: Calder Travel GmbH | I3: Consumer Products | J3: 5122 | K3: 5122 | L3: 353587990 | M3: 353587990 | N3: Business chemistry & scoping | O3: 45487 | P3: 45669 | Q3: Q1-2025 | R3: 78800 | S3: =IF(N3="Closed Won","",P3-ReportDate) -> -186 | T3: =IF(N3="Closed Won","closed",IF(S3<0,"past closed",IF(S3<=10,"update","on track"))) -> past closed | U3: =IF(H3="","No D&B match",IF(TRIM(G3)=TRIM(H3),"Match","Mismatch")) -> Match | V3: =IF(K3="","No D&B match",IF(J3="","Missing in CRM",IF(J3=K3,"Match","Mismatch"))) -> Match | W3: =IF(M3="","No D&B match",IF(L3="","Missing in CRM",IF(L3=M3,"Match","Mismatch"))) -> Match | X3: =COUNTIF(U3:W3,"<>Match")+IF(T3="past closed",1,0) -> 1 | Y3: =IF(X3=0,"Clean","Review") -> Review
A4: 001SYN000003 | B4: 006SYN000000003 | C4: DK | D4: EMEA NORTH | E4: 24/Core-Adv-Omni/44K/Larch | F4: Owner EN07 | G4: Larch Fashion A/S | H4: Larch Fashion A/S | I4: Financial Services | J4: 6022 | K4: 6022 | L4: 431589562 | M4: 431589562 | N4: Business chemistry & scoping | O4: 45492 | P4: 45652 | Q4: Q4-2024 | R4: 44500 | S4: =IF(N4="Closed Won","",P4-ReportDate) -> -203 | T4: =IF(N4="Closed Won","closed",IF(S4<0,"past closed",IF(S4<=10,"update","on track"))) -> past closed | U4: =IF(H4="","No D&B match",IF(TRIM(G4)=TRIM(H4),"Match","Mismatch")) -> Match | V4: =IF(K4="","No D&B match",IF(J4="","Missing in CRM",IF(J4=K4,"Match","Mismatch"))) -> Match | W4: =IF(M4="","No D&B match",IF(L4="","Missing in CRM",IF(L4=M4,"Match","Mismatch"))) -> Match | X4: =COUNTIF(U4:W4,"<>Match")+IF(T4="past closed",1,0) -> 1 | Y4: =IF(X4=0,"Clean","Review") -> Review
A5: 001SYN000004 | B5: 006SYN000000004 | C5: CZ | D5: MEE | E5: 24/Core-Adv-Omni/21K/Dunmore | F5: Owner ME06 | G5: Dunmore Sport s.r.o. | H5: Dunmore Sport s.r.o. | I5: Financial Services | J5: 8062 | K5: 6022 | L5: 206692057 | M5: 332936552 | N5: Closed Won | O5: 45578 | P5: 45631 | Q5: Q4-2024 | R5: 21000 | S5: =IF(N5="Closed Won","",P5-ReportDate) | T5: =IF(N5="Closed Won","closed",IF(S5<0,"past closed",IF(S5<=10,"update","on track"))) -> closed | U5: =IF(H5="","No D&B match",IF(TRIM(G5)=TRIM(H5),"Match","Mismatch")) -> Match | V5: =IF(K5="","No D&B match",IF(J5="","Missing in CRM",IF(J5=K5,"Match","Mismatch"))) -> Mismatch | W5: =IF(M5="","No D&B match",IF(L5="","Missing in CRM",IF(L5=M5,"Match","Mismatch"))) -> Mismatch | X5: =COUNTIF(U5:W5,"<>Match")+IF(T5="past closed",1,0) -> 2 | Y5: =IF(X5=0,"Clean","Review") -> Review
A6: 001SYN000005 | B6: 006SYN000000005 | C6: IT | D6: EMEA SOUTH | E6: 24/Core-Adv-Omni/98K/Penrose | F6: Owner ES06 | G6: Penrose Wine S.p.A. | H6: Penrose Wine S.p.A. | I6: Automotive | J6: 5511 | K6: 5511 | L6: 732167482 | M6: 732167482 | N6: Business chemistry & scoping | O6: 45488 | P6: 45785 | Q6: Q2-2025 | R6: 98500 | S6: =IF(N6="Closed Won","",P6-ReportDate) -> -70 | T6: =IF(N6="Closed Won","closed",IF(S6<0,"past closed",IF(S6<=10,"update","on track"))) -> past closed | U6: =IF(H6="","No D&B match",IF(TRIM(G6)=TRIM(H6),"Match","Mismatch")) -> Match | V6: =IF(K6="","No D&B match",IF(J6="","Missing in CRM",IF(J6=K6,"Match","Mismatch"))) -> Match | W6: =IF(M6="","No D&B match",IF(L6="","Missing in CRM",IF(L6=M6,"Match","Mismatch"))) -> Match | X6: =COUNTIF(U6:W6,"<>Match")+IF(T6="past closed",1,0) -> 1 | Y6: =IF(X6=0,"Clean","Review") -> Review
A7: 001SYN000006 | B7: 006SYN000000006 | C7: AT | D7: MEE | E7: 36/Core-Adv-Omni/210K/Quill | F7: Owner ME06 | G7: Quill Home GmbH | H7: Quill Home GmbH | I7: Automotive | J7: 5511 | K7: 5511 | L7: 886957553 | M7: 886957553 | N7: Tech agreement | O7: 45336 | P7: 45607 | Q7: Q4-2024 | R7: 210900 | S7: =IF(N7="Closed Won","",P7-ReportDate) -> -248 | T7: =IF(N7="Closed Won","closed",IF(S7<0,"past closed",IF(S7<=10,"update","on track"))) -> past closed | U7: =IF(H7="","No D&B match",IF(TRIM(G7)=TRIM(H7),"Match","Mismatch")) -> Match | V7: =IF(K7="","No D&B match",IF(J7="","Missing in CRM",IF(J7=K7,"Match","Mismatch"))) -> Match | W7: =IF(M7="","No D&B match",IF(L7="","Missing in CRM",IF(L7=M7,"Match","Mismatch"))) -> Match | X7: =COUNTIF(U7:W7,"<>Match")+IF(T7="past closed",1,0) -> 1 | Y7: =IF(X7=0,"Clean","Review") -> Review
A8: 001SYN000007 | B8: 006SYN000000007 | C8: NL | D8: EMEA NORTH | E8: 12/Core+Loyalty/130K/Redfern | F8: Owner EN07 | G8: Redfern Living B.V. | H8: Redfern Living B.V. | I8: Travel & Hospitality | J8: 7011 | K8: 7011 | L8: 627554006 | M8: 627554006 | N8: Solution presentation | O8: 45568 | P8: 45853 | Q8: Q3-2025 | R8: 130100 | S8: =IF(N8="Closed Won","",P8-ReportDate) -> -2 | T8: =IF(N8="Closed Won","closed",IF(S8<0,"past closed",IF(S8<=10,"update","on track"))) -> past closed | U8: =IF(H8="","No D&B match",IF(TRIM(G8)=TRIM(H8),"Match","Mismatch")) -> Match | V8: =IF(K8="","No D&B match",IF(J8="","Missing in CRM",IF(J8=K8,"Match","Mismatch"))) -> Match | W8: =IF(M8="","No D&B match",IF(L8="","Missing in CRM",IF(L8=M8,"Match","Mismatch"))) -> Match | X8: =COUNTIF(U8:W8,"<>Match")+IF(T8="past closed",1,0) -> 1 | Y8: =IF(X8=0,"Clean","Review") -> Review
A9: 001SYN000008 | B9: 006SYN000000008 | C9: DE | D9: MEE | E9: 24/Core+Omni/57K/Quill | F9: Owner ME07 | G9: Quill Retail GmbH | H9: Quill Retail GmbH | I9: Automotive | J9: 5511 | K9: 5511 | L9: 640159497 | M9: 640159497 | N9: Closed Won | O9: 45556 | P9: 45801 | Q9: Q2-2025 | R9: 57000 | S9: =IF(N9="Closed Won","",P9-ReportDate) | T9: =IF(N9="Closed Won","closed",IF(S9<0,"past closed",IF(S9<=10,"update","on track"))) -> closed | U9: =IF(H9="","No D&B match",IF(TRIM(G9)=TRIM(H9),"Match","Mismatch")) -> Match | V9: =IF(K9="","No D&B match",IF(J9="","Missing in CRM",IF(J9=K9,"Match","Mismatch"))) -> Match | W9: =IF(M9="","No D&B match",IF(L9="","Missing in CRM",IF(L9=M9,"Match","Mismatch"))) -> Match | X9: =COUNTIF(U9:W9,"<>Match")+IF(T9="past closed",1,0) -> 0 | Y9: =IF(X9=0,"Clean","Review") -> Clean
A10: 001SYN000009 | B10: 006SYN000000009 | C10: CN | D10: GCN | E10: 12/Core-Adv-Omni/34K/Carrow | F10: Owner GC02 | G10: Carrow Motors Co., Ltd | H10: Carrow Motors Co., Ltd | I10: Media | J10: 4841 | K10: 4841 | L10: 847038506 | M10: 847038506 | N10: Business chemistry & scoping | O10: 45425 | P10: 45470 | Q10: Q2-2024 | R10: 34100 | S10: =IF(N10="Closed Won","",P10-ReportDate) -> -385 | T10: =IF(N10="Closed Won","closed",IF(S10<0,"past closed",IF(S10<=10,"update","on track"))) -> past closed | U10: =IF(H10="","No D&B match",IF(TRIM(G10)=TRIM(H10),"Match","Mismatch")) -> Match | V10: =IF(K10="","No D&B match",IF(J10="","Missing in CRM",IF(J10=K10,"Match","Mismatch"))) -> Match | W10: =IF(M10="","No D&B match",IF(L10="","Missing in CRM",IF(L10=M10,"Match","Mismatch"))) -> Match | X10: =COUNTIF(U10:W10,"<>Match")+IF(T10="past closed",1,0) -> 1 | Y10: =IF(X10=0,"Clean","Review") -> Review
A11: 001SYN000010 | B11: 006SYN000000010 | C11: PL | D11: MEE | E11: 24/Core+Ecom/278K/Tavish | F11: Owner ME01 | G11: Tavish Travel Sp. z o.o. | H11: Tavish Travel Sp. z o.o. | I11: Automotive | K11: 5511 | M11: 661600782 | N11: Business chemistry & scoping | O11: 45310 | P11: 45502 | Q11: Q3-2024 | R11: 278500 | S11: =IF(N11="Closed Won","",P11-ReportDate) -> -353 | T11: =IF(N11="Closed Won","closed",IF(S11<0,"past closed",IF(S11<=10,"update","on track"))) -> past closed | U11: =IF(H11="","No D&B match",IF(TRIM(G11)=TRIM(H11),"Match","Mismatch")) -> Match | V11: =IF(K11="","No D&B match",IF(J11="","Missing in CRM",IF(J11=K11,"Match","Mismatch"))) -> Missing in CRM | W11: =IF(M11="","No D&B match",IF(L11="","Missing in CRM",IF(L11=M11,"Match","Mismatch"))) -> Missing in CRM | X11: =COUNTIF(U11:W11,"<>Match")+IF(T11="past closed",1,0) -> 3 | Y11: =IF(X11=0,"Clean","Review") -> Review
A12: 001SYN000011 | B12: 006SYN000000011 | C12: TR | D12: EMEA SOUTH | E12: 36/Essentials+Mob/100K/Marlow | F12: Owner ES01 | G12: Marlow Brands A.S. | H12: Marlow Brands A.S. Group | I12: eCommerce | J12: 5961 | K12: 5961 | L12: 348098165 | M12: 348098165 | N12: Business chemistry & scoping | O12: 45598 | P12: 45737 | Q12: Q1-2025 | R12: 100200 | S12: =IF(N12="Closed Won","",P12-ReportDate) -> -118 | T12: =IF(N12="Closed Won","closed",IF(S12<0,"past closed",IF(S12<=10,"update","on track"))) -> past closed | U12: =IF(H12="","No D&B match",IF(TRIM(G12)=TRIM(H12),"Match","Mismatch")) -> Mismatch | V12: =IF(K12="","No D&B match",IF(J12="","Missing in CRM",IF(J12=K12,"Match","Mismatch"))) -> Match | W12: =IF(M12="","No D&B match",IF(L12="","Missing in CRM",IF(L12=M12,"Match","Mismatch"))) -> Match | X12: =COUNTIF(U12:W12,"<>Match")+IF(T12="past closed",1,0) -> 2 | Y12: =IF(X12=0,"Clean","Review") -> Review
A13: 001SYN000012 | B13: 006SYN000000012 | C13: PL | D13: MEE | E13: 12/Core-Adv-Omni/329K/Fenwick | F13: Owner ME09 | G13: Fenwick Sport Sp. z o.o. | H13: Fenwick Sport Sp. z o.o. | I13: Automotive | J13: 5511 | K13: 5511 | L13: 957417959 | M13: 957417959 | N13: Solution presentation | O13: 45488 | P13: 45775 | Q13: Q2-2025 | R13: 329400 | S13: =IF(N13="Closed Won","",P13-ReportDate) -> -80 | T13: =IF(N13="Closed Won","closed",IF(S13<0,"past closed",IF(S13<=10,"update","on track"))) -> past closed | U13: =IF(H13="","No D&B match",IF(TRIM(G13)=TRIM(H13),"Match","Mismatch")) -> Match | V13: =IF(K13="","No D&B match",IF(J13="","Missing in CRM",IF(J13=K13,"Match","Mismatch"))) -> Match | W13: =IF(M13="","No D&B match",IF(L13="","Missing in CRM",IF(L13=M13,"Match","Mismatch"))) -> Match | X13: =COUNTIF(U13:W13,"<>Match")+IF(T13="past closed",1,0) -> 1 | Y13: =IF(X13=0,"Clean","Review") -> Review
A14: 001SYN000013 | B14: 006SYN000000013 | C14: NL | D14: EMEA NORTH | E14: 12/Core-Adv-Omni/78K/Alder | F14: Owner EN01 | G14: Alder Foods B.V. | H14: Alder Foods B.V. | I14: Consumer Products | J14: 5122 | K14: 5122 | L14: 784010171 | M14: 784010171 | N14: Solution presentation | O14: 45403 | P14: 45629 | Q14: Q4-2024 | R14: 78200 | S14: =IF(N14="Closed Won","",P14-ReportDate) -> -226 | T14: =IF(N14="Closed Won","closed",IF(S14<0,"past closed",IF(S14<=10,"update","on track"))) -> past closed | U14: =IF(H14="","No D&B match",IF(TRIM(G14)=TRIM(H14),"Match","Mismatch")) -> Match | V14: =IF(K14="","No D&B match",IF(J14="","Missing in CRM",IF(J14=K14,"Match","Mismatch"))) -> Match | W14: =IF(M14="","No D&B match",IF(L14="","Missing in CRM",IF(L14=M14,"Match","Mismatch"))) -> Match | X14: =COUNTIF(U14:W14,"<>Match")+IF(T14="past closed",1,0) -> 1 | Y14: =IF(X14=0,"Clean","Review") -> Review
A15: 001SYN000014 | B15: 006SYN000000014 | C15: AU | D15: APJ | E15: 12/Core+Loyalty/198K/Holloway | F15: Owner AP01 | G15: Holloway Pharma Pty Ltd | I15: Retail | N15: Business chemistry & scoping | O15: 45774 | P15: 45846 | Q15: Q3-2025 | R15: 198300 | S15: =IF(N15="Closed Won","",P15-ReportDate) -> -9 | T15: =IF(N15="Closed Won","closed",IF(S15<0,"past closed",IF(S15<=10,"update","on track"))) -> past closed | U15: =IF(H15="","No D&B match",IF(TRIM(G15)=TRIM(H15),"Match","Mismatch")) -> No D&B match | V15: =IF(K15="","No D&B match",IF(J15="","Missing in CRM",IF(J15=K15,"Match","Mismatch"))) -> No D&B match | W15: =IF(M15="","No D&B match",IF(L15="","Missing in CRM",IF(L15=M15,"Match","Mismatch"))) -> No D&B match | X15: =COUNTIF(U15:W15,"<>Match")+IF(T15="past closed",1,0) -> 4 | Y15: =IF(X15=0,"Clean","Review") -> Review
A16: 001SYN000015 | B16: 006SYN000000015 | C16: ES | D16: EMEA SOUTH | E16: 24/Core+Ecom+Omni/66K/Corvale | F16: Owner ES05 | G16: Corvale Motors S.L. | H16: Corvale Motors S.L. | I16: Automotive | J16: 5511 | K16: 5511 | L16: 951539705 | M16: 156183962 | N16: Business chemistry & scoping | O16: 45314 | P16: 45501 | Q16: Q3-2024 | R16: 66400 | S16: =IF(N16="Closed Won","",P16-ReportDate) -> -354 | T16: =IF(N16="Closed Won","closed",IF(S16<0,"past closed",IF(S16<=10,"update","on track"))) -> past closed | U16: =IF(H16="","No D&B match",IF(TRIM(G16)=TRIM(H16),"Match","Mismatch")) -> Match | V16: =IF(K16="","No D&B match",IF(J16="","Missing in CRM",IF(J16=K16,"Match","Mismatch"))) -> Match | W16: =IF(M16="","No D&B match",IF(L16="","Missing in CRM",IF(L16=M16,"Match","Mismatch"))) -> Mismatch | X16: =COUNTIF(U16:W16,"<>Match")+IF(T16="past closed",1,0) -> 2 | Y16: =IF(X16=0,"Clean","Review") -> Review
A17: 001SYN000016 | B17: 006SYN000000016 | C17: MX | D17: LATAM | E17: 36/Essentials+Mob/53K/Merrow | F17: Owner LA02 | G17: Merrow Sport S.A. de C.V. | H17: Merrow Sport S.A. de C.V. | I17: eCommerce | J17: 5961 | K17: 5961 | L17: 736240885 | M17: 946590519 | N17: Business chemistry & scoping | O17: 45753 | P17: 46008 | Q17: Q4-2025 | R17: 53500 | S17: =IF(N17="Closed Won","",P17-ReportDate) -> 153 | T17: =IF(N17="Closed Won","closed",IF(S17<0,"past closed",IF(S17<=10,"update","on track"))) -> on track | U17: =IF(H17="","No D&B match",IF(TRIM(G17)=TRIM(H17),"Match","Mismatch")) -> Match | V17: =IF(K17="","No D&B match",IF(J17="","Missing in CRM",IF(J17=K17,"Match","Mismatch"))) -> Match | W17: =IF(M17="","No D&B match",IF(L17="","Missing in CRM",IF(L17=M17,"Match","Mismatch"))) -> Mismatch | X17: =COUNTIF(U17:W17,"<>Match")+IF(T17="past closed",1,0) -> 1 | Y17: =IF(X17=0,"Clean","Review") -> Review
A18: 001SYN000017 | B18: 006SYN000000017 | C18: NL | D18: EMEA NORTH | E18: 24/Core+Ecom/53K/Oriel | F18: Owner EN05 | G18: Oriel Media B.V. | H18: Oriel Media BV | I18: Automotive | J18: 5511 | K18: 5511 | L18: 724906726 | M18: 724906726 | N18: Commercial agreement | O18: 45294 | P18: 45445 | Q18: Q2-2024 | R18: 53400 | S18: =IF(N18="Closed Won","",P18-ReportDate) -> -410 | T18: =IF(N18="Closed Won","closed",IF(S18<0,"past closed",IF(S18<=10,"update","on track"))) -> past closed | U18: =IF(H18="","No D&B match",IF(TRIM(G18)=TRIM(H18),"Match","Mismatch")) -> Mismatch | V18: =IF(K18="","No D&B match",IF(J18="","Missing in CRM",IF(J18=K18,"Match","Mismatch"))) -> Match | W18: =IF(M18="","No D&B match",IF(L18="","Missing in CRM",IF(L18=M18,"Match","Mismatch"))) -> Match | X18: =COUNTIF(U18:W18,"<>Match")+IF(T18="past closed",1,0) -> 2 | Y18: =IF(X18=0,"Clean","Review") -> Review
A19: 001SYN000018 | B19: 006SYN000000018 | C19: US | D19: NA | E19: 12/Essentials+Mob/56K/Larch | F19: Owner NA01 | G19: Larch Optics Inc. | H19: Larch Optics Inc. | I19: Financial Services | J19: 6022 | K19: 6022 | L19: 692056865 | M19: 692056865 | N19: Closed Won | O19: 45368 | P19: 45609 | Q19: Q4-2024 | R19: 56900 | S19: =IF(N19="Closed Won","",P19-ReportDate) | T19: =IF(N19="Closed Won","closed",IF(S19<0,"past closed",IF(S19<=10,"update","on track"))) -> closed | U19: =IF(H19="","No D&B match",IF(TRIM(G19)=TRIM(H19),"Match","Mismatch")) -> Match | V19: =IF(K19="","No D&B match",IF(J19="","Missing in CRM",IF(J19=K19,"Match","Mismatch"))) -> Match | W19: =IF(M19="","No D&B match",IF(L19="","Missing in CRM",IF(L19=M19,"Match","Mismatch"))) -> Match | X19: =COUNTIF(U19:W19,"<>Match")+IF(T19="past closed",1,0) -> 0 | Y19: =IF(X19=0,"Clean","Review") -> Clean
A20: 001SYN000019 | B20: 006SYN000000019 | C20: CA | D20: NA | E20: 12/Core+Omni/224K/Arden | F20: Owner NA01 | G20: Arden Optics Inc. | I20: Financial Services | N20: Closed Won | O20: 45338 | P20: 45476 | Q20: Q3-2024 | R20: 224200 | S20: =IF(N20="Closed Won","",P20-ReportDate) | T20: =IF(N20="Closed Won","closed",IF(S20<0,"past closed",IF(S20<=10,"update","on track"))) -> closed | U20: =IF(H20="","No D&B match",IF(TRIM(G20)=TRIM(H20),"Match","Mismatch")) -> No D&B match | V20: =IF(K20="","No D&B match",IF(J20="","Missing in CRM",IF(J20=K20,"Match","Mismatch"))) -> No D&B match | W20: =IF(M20="","No D&B match",IF(L20="","Missing in CRM",IF(L20=M20,"Match","Mismatch"))) -> No D&B match | X20: =COUNTIF(U20:W20,"<>Match")+IF(T20="past closed",1,0) -> 3 | Y20: =IF(X20=0,"Clean","Review") -> Review
A21: 001SYN000020 | B21: 006SYN000000020 | C21: CN | D21: GCN | E21: 36/Essentials+Mob/87K/Dunmore | F21: Owner GC01 | G21: Dunmore Home Co., Ltd | H21: Dunmore Home Co., Ltd | I21: eCommerce | J21: 5961 | K21: 5961 | L21: 433836604 | M21: 433836604 | N21: Solution presentation | O21: 45414 | P21: 45672 | Q21: Q1-2025 | R21: 87300 | S21: =IF(N21="Closed Won","",P21-ReportDate) -> -183 | T21: =IF(N21="Closed Won","closed",IF(S21<0,"past closed",IF(S21<=10,"update","on track"))) -> past closed | U21: =IF(H21="","No D&B match",IF(TRIM(G21)=TRIM(H21),"Match","Mismatch")) -> Match | V21: =IF(K21="","No D&B match",IF(J21="","Missing in CRM",IF(J21=K21,"Match","Mismatch"))) -> Match | W21: =IF(M21="","No D&B match",IF(L21="","Missing in CRM",IF(L21=M21,"Match","Mismatch"))) -> Match | X21: =COUNTIF(U21:W21,"<>Match")+IF(T21="past closed",1,0) -> 1 | Y21: =IF(X21=0,"Clean","Review") -> Review
A22: 001SYN000021 | B22: 006SYN000000021 | C22: SE | D22: EMEA NORTH | E22: 12/Core+Ecom+Omni/50K/Marlow | F22: Owner EN03 | G22: Marlow Travel AB | H22: Marlow Travel AB | I22: Retail | J22: 5999 | K22: 5999 | L22: 315165225 | M22: 315165225 | N22: Solution presentation | O22: 45609 | P22: 45655 | Q22: Q4-2024 | R22: 50400 | S22: =IF(N22="Closed Won","",P22-ReportDate) -> -200 | T22: =IF(N22="Closed Won","closed",IF(S22<0,"past closed",IF(S22<=10,"update","on track"))) -> past closed | U22: =IF(H22="","No D&B match",IF(TRIM(G22)=TRIM(H22),"Match","Mismatch")) -> Match | V22: =IF(K22="","No D&B match",IF(J22="","Missing in CRM",IF(J22=K22,"Match","Mismatch"))) -> Match | W22: =IF(M22="","No D&B match",IF(L22="","Missing in CRM",IF(L22=M22,"Match","Mismatch"))) -> Match | X22: =COUNTIF(U22:W22,"<>Match")+IF(T22="past closed",1,0) -> 1 | Y22: =IF(X22=0,"Clean","Review") -> Review
A23: 001SYN000022 | B23: 006SYN000000022 | C23: AR | D23: LATAM | E23: 24/Essentials+Mob/162K/Fenwick | F23: Owner LA03 | G23: Fenwick Brands S.A. | H23: Fenwick Brands S.A. | I23: Travel & Hospitality | J23: 7011 | K23: 7011 | L23: 934006341 | M23: 934006341 | N23: Commercial agreement | O23: 45721 | P23: 45958 | Q23: Q4-2025 | R23: 162800 | S23: =IF(N23="Closed Won","",P23-ReportDate) -> 103 | T23: =IF(N23="Closed Won","closed",IF(S23<0,"past closed",IF(S23<=10,"update","on track"))) -> on track | U23: =IF(H23="","No D&B match",IF(TRIM(G23)=TRIM(H23),"Match","Mismatch")) -> Match | V23: =IF(K23="","No D&B match",IF(J23="","Missing in CRM",IF(J23=K23,"Match","Mismatch"))) -> Match | W23: =IF(M23="","No D&B match",IF(L23="","Missing in CRM",IF(L23=M23,"Match","Mismatch"))) -> Match | X23: =COUNTIF(U23:W23,"<>Match")+IF(T23="past closed",1,0) -> 0 | Y23: =IF(X23=0,"Clean","Review") -> Clean
A24: 001SYN000023 | B24: 006SYN000000023 | C24: AT | D24: MEE | E24: 24/Core+Ecom/269K/North | F24: Owner ME03 | G24: North Fashion GmbH | H24: North Fashion GmbH | I24: Automotive | J24: 5511 | K24: 5511 | L24: 240881601 | M24: 240881601 | N24: Solution presentation | O24: 45317 | P24: 45382 | Q24: Q1-2024 | R24: 269600 | S24: =IF(N24="Closed Won","",P24-ReportDate) -> -473 | T24: =IF(N24="Closed Won","closed",IF(S24<0,"past closed",IF(S24<=10,"update","on track"))) -> past closed | U24: =IF(H24="","No D&B match",IF(TRIM(G24)=TRIM(H24),"Match","Mismatch")) -> Match | V24: =IF(K24="","No D&B match",IF(J24="","Missing in CRM",IF(J24=K24,"Match","Mismatch"))) -> Match | W24: =IF(M24="","No D&B match",IF(L24="","Missing in CRM",IF(L24=M24,"Match","Mismatch"))) -> Match | X24: =COUNTIF(U24:W24,"<>Match")+IF(T24="past closed",1,0) -> 1 | Y24: =IF(X24=0,"Clean","Review") -> Review
A25: 001SYN000024 | B25: 006SYN000000024 | C25: AE | D25: EMEA SOUTH | E25: 24/Core+Ecom+Omni/37K/Penrose | F25: Owner ES06 | G25: Penrose Pharma LLC | H25: Penrose Pharma LLC Group | I25: eCommerce | J25: 5961 | K25: 5961 | L25: 140827458 | M25: 140827458 | N25: Solution presentation | O25: 45547 | P25: 45802 | Q25: Q2-2025 | R25: 37900 | S25: =IF(N25="Closed Won","",P25-ReportDate) -> -53 | T25: =IF(N25="Closed Won","closed",IF(S25<0,"past closed",IF(S25<=10,"update","on track"))) -> past closed | U25: =IF(H25="","No D&B match",IF(TRIM(G25)=TRIM(H25),"Match","Mismatch")) -> Mismatch | V25: =IF(K25="","No D&B match",IF(J25="","Missing in CRM",IF(J25=K25,"Match","Mismatch"))) -> Match | W25: =IF(M25="","No D&B match",IF(L25="","Missing in CRM",IF(L25=M25,"Match","Mismatch"))) -> Match | X25: =COUNTIF(U25:W25,"<>Match")+IF(T25="past closed",1,0) -> 2 | Y25: =IF(X25=0,"Clean","Review") -> Review
A26: 001SYN000025 | B26: 006SYN000000025 | C26: DK | D26: EMEA NORTH | E26: 36/Core-Adv-Omni/116K/North | F26: Owner EN02 | G26: North Beauty A/S | H26: North Beauty A/S | I26: Retail | J26: 5999 | K26: 5999 | L26: 284497694 | M26: 284497694 | N26: Tech agreement | O26: 45551 | P26: 45635 | Q26: Q4-2024 | R26: 116200 | S26: =IF(N26="Closed Won","",P26-ReportDate) -> -220 | T26: =IF(N26="Closed Won","closed",IF(S26<0,"past closed",IF(S26<=10,"update","on track"))) -> past closed | U26: =IF(H26="","No D&B match",IF(TRIM(G26)=TRIM(H26),"Match","Mismatch")) -> Match | V26: =IF(K26="","No D&B match",IF(J26="","Missing in CRM",IF(J26=K26,"Match","Mismatch"))) -> Match | W26: =IF(M26="","No D&B match",IF(L26="","Missing in CRM",IF(L26=M26,"Match","Mismatch"))) -> Match | X26: =COUNTIF(U26:W26,"<>Match")+IF(T26="past closed",1,0) -> 1 | Y26: =IF(X26=0,"Clean","Review") -> Review
A27: 001SYN000026 | B27: 006SYN000000026 | C27: DE | D27: MEE | E27: 12/Essentials+Mob/268K/Carrow | F27: Owner ME07 | G27: Carrow Fashion GmbH | H27: Carrow Fashion GmbH | I27: Healthcare | K27: 8062 | M27: 532093736 | N27: Commercial agreement | O27: 45404 | P27: 45469 | Q27: Q2-2024 | R27: 268800 | S27: =IF(N27="Closed Won","",P27-ReportDate) -> -386 | T27: =IF(N27="Closed Won","closed",IF(S27<0,"past closed",IF(S27<=10,"update","on track"))) -> past closed | U27: =IF(H27="","No D&B match",IF(TRIM(G27)=TRIM(H27),"Match","Mismatch")) -> Match | V27: =IF(K27="","No D&B match",IF(J27="","Missing in CRM",IF(J27=K27,"Match","Mismatch"))) -> Missing in CRM | W27: =IF(M27="","No D&B match",IF(L27="","Missing in CRM",IF(L27=M27,"Match","Mismatch"))) -> Missing in CRM | X27: =COUNTIF(U27:W27,"<>Match")+IF(T27="past closed",1,0) -> 3 | Y27: =IF(X27=0,"Clean","Review") -> Review
A28: 001SYN000027 | B28: 006SYN000000027 | C28: CH | D28: MEE | E28: 12/Core+Loyalty/268K/Elstree | F28: Owner ME03 | G28: Elstree Brands AG | I28: Consumer Products | N28: Business chemistry & scoping | O28: 45589 | P28: 45880 | Q28: Q3-2025 | R28: 268700 | S28: =IF(N28="Closed Won","",P28-ReportDate) -> 25 | T28: =IF(N28="Closed Won","closed",IF(S28<0,"past closed",IF(S28<=10,"update","on track"))) -> on track | U28: =IF(H28="","No D&B match",IF(TRIM(G28)=TRIM(H28),"Match","Mismatch")) -> No D&B match | V28: =IF(K28="","No D&B match",IF(J28="","Missing in CRM",IF(J28=K28,"Match","Mismatch"))) -> No D&B match | W28: =IF(M28="","No D&B match",IF(L28="","Missing in CRM",IF(L28=M28,"Match","Mismatch"))) -> No D&B match | X28: =COUNTIF(U28:W28,"<>Match")+IF(T28="past closed",1,0) -> 3 | Y28: =IF(X28=0,"Clean","Review") -> Review
A29: 001SYN000028 | B29: 006SYN000000028 | C29: AU | D29: APJ | E29: 36/Core+Ecom+Omni/51K/Penrose | F29: Owner AP02 | G29: Penrose Media Pty Ltd | H29: Penrose Media Pty Ltd | I29: Healthcare | J29: 5961 | K29: 8062 | L29: 735301396 | M29: 421429343 | N29: Solution presentation | O29: 45743 | P29: 45934 | Q29: Q4-2025 | R29: 51000 | S29: =IF(N29="Closed Won","",P29-ReportDate) -> 79 | T29: =IF(N29="Closed Won","closed",IF(S29<0,"past closed",IF(S29<=10,"update","on track"))) -> on track | U29: =IF(H29="","No D&B match",IF(TRIM(G29)=TRIM(H29),"Match","Mismatch")) -> Match | V29: =IF(K29="","No D&B match",IF(J29="","Missing in CRM",IF(J29=K29,"Match","Mismatch"))) -> Mismatch | W29: =IF(M29="","No D&B match",IF(L29="","Missing in CRM",IF(L29=M29,"Match","Mismatch"))) -> Mismatch | X29: =COUNTIF(U29:W29,"<>Match")+IF(T29="past closed",1,0) -> 2 | Y29: =IF(X29=0,"Clean","Review") -> Review
A30: 001SYN000029 | B30: 006SYN000000029 | C30: CN | D30: GCN | E30: 36/Core+Omni/31K/Dunmore | F30: Owner GC01 | G30: Dunmore Beauty Co., Ltd | H30: Dunmore Beauty Co., Ltd | I30: Automotive | K30: 5511 | M30: 965590147 | N30: Business chemistry & scoping | O30: 45643 | P30: 45777 | Q30: Q2-2025 | R30: 31500 | S30: =IF(N30="Closed Won","",P30-ReportDate) -> -78 | T30: =IF(N30="Closed Won","closed",IF(S30<0,"past closed",IF(S30<=10,"update","on track"))) -> past closed | U30: =IF(H30="","No D&B match",IF(TRIM(G30)=TRIM(H30),"Match","Mismatch")) -> Match | V30: =IF(K30="","No D&B match",IF(J30="","Missing in CRM",IF(J30=K30,"Match","Mismatch"))) -> Missing in CRM | W30: =IF(M30="","No D&B match",IF(L30="","Missing in CRM",IF(L30=M30,"Match","Mismatch"))) -> Missing in CRM | X30: =COUNTIF(U30:W30,"<>Match")+IF(T30="past closed",1,0) -> 3 | Y30: =IF(X30=0,"Clean","Review") -> Review
A31: 001SYN000030 | B31: 006SYN000000030 | C31: TR | D31: EMEA SOUTH | E31: 12/Essentials+Mob/70K/Linden | F31: Owner ES01 | G31: Linden Living A.S. | H31: Linden Living A.S. | I31: Media | J31: 4841 | K31: 4841 | L31: 292970593 | M31: 292970593 | N31: Solution presentation | O31: 45336 | P31: 45428 | Q31: Q2-2024 | R31: 70800 | S31: =IF(N31="Closed Won","",P31-ReportDate) -> -427 | T31: =IF(N31="Closed Won","closed",IF(S31<0,"past closed",IF(S31<=10,"update","on track"))) -> past closed | U31: =IF(H31="","No D&B match",IF(TRIM(G31)=TRIM(H31),"Match","Mismatch")) -> Match | V31: =IF(K31="","No D&B match",IF(J31="","Missing in CRM",IF(J31=K31,"Match","Mismatch"))) -> Match | W31: =IF(M31="","No D&B match",IF(L31="","Missing in CRM",IF(L31=M31,"Match","Mismatch"))) -> Match | X31: =COUNTIF(U31:W31,"<>Match")+IF(T31="past closed",1,0) -> 1 | Y31: =IF(X31=0,"Clean","Review") -> Review
A32: 001SYN000031 | B32: 006SYN000000031 | C32: CA | D32: NA | E32: 12/Core+Loyalty/20K/Carrow | F32: Owner NA06 | G32: Carrow Foods Inc. | H32: Carrow Foods Inc. | I32: Healthcare | J32: 8062 | K32: 8062 | L32: 881797601 | M32: 881797601 | N32: Business chemistry & scoping | O32: 45574 | P32: 45754 | Q32: Q2-2025 | R32: 20900 | S32: =IF(N32="Closed Won","",P32-ReportDate) -> -101 | T32: =IF(N32="Closed Won","closed",IF(S32<0,"past closed",IF(S32<=10,"update","on track"))) -> past closed | U32: =IF(H32="","No D&B match",IF(TRIM(G32)=TRIM(H32),"Match","Mismatch")) -> Match | V32: =IF(K32="","No D&B match",IF(J32="","Missing in CRM",IF(J32=K32,"Match","Mismatch"))) -> Match | W32: =IF(M32="","No D&B match",IF(L32="","Missing in CRM",IF(L32=M32,"Match","Mismatch"))) -> Match | X32: =COUNTIF(U32:W32,"<>Match")+IF(T32="past closed",1,0) -> 1 | Y32: =IF(X32=0,"Clean","Review") -> Review
A33: 001SYN000032 | B33: 006SYN000000032 | C33: AU | D33: APJ | E33: 24/Core+Ecom+Omni/102K/Carrow | F33: Owner AP01 | G33: Carrow Retail Pty Ltd | H33: Carrow Retail Pty Ltd | I33: Media | J33: 4841 | K33: 4841 | L33: 110499490 | M33: 110499490 | N33: Solution presentation | O33: 45729 | P33: 45880 | Q33: Q3-2025 | R33: 102500 | S33: =IF(N33="Closed Won","",P33-ReportDate) -> 25 | T33: =IF(N33="Closed Won","closed",IF(S33<0,"past closed",IF(S33<=10,"update","on track"))) -> on track | U33: =IF(H33="","No D&B match",IF(TRIM(G33)=TRIM(H33),"Match","Mismatch")) -> Match | V33: =IF(K33="","No D&B match",IF(J33="","Missing in CRM",IF(J33=K33,"Match","Mismatch"))) -> Match | W33: =IF(M33="","No D&B match",IF(L33="","Missing in CRM",IF(L33=M33,"Match","Mismatch"))) -> Match | X33: =COUNTIF(U33:W33,"<>Match")+IF(T33="past closed",1,0) -> 0 | Y33: =IF(X33=0,"Clean","Review") -> Clean
A34: 001SYN000033 | B34: 006SYN000000033 | C34: IT | D34: EMEA SOUTH | E34: 24/Core+Omni/171K/Calder | F34: Owner ES02 | G34: Calder Retail S.p.A. | H34: Calder Retail S.p.A. | I34: Healthcare | J34: 8062 | K34: 8062 | L34: 616159236 | M34: 616159236 | N34: Closed Won | O34: 45330 | P34: 45559 | Q34: Q3-2024 | R34: 171200 | S34: =IF(N34="Closed Won","",P34-ReportDate) | T34: =IF(N34="Closed Won","closed",IF(S34<0,"past closed",IF(S34<=10,"update","on track"))) -> closed | U34: =IF(H34="","No D&B match",IF(TRIM(G34)=TRIM(H34),"Match","Mismatch")) -> Match | V34: =IF(K34="","No D&B match",IF(J34="","Missing in CRM",IF(J34=K34,"Match","Mismatch"))) -> Match | W34: =IF(M34="","No D&B match",IF(L34="","Missing in CRM",IF(L34=M34,"Match","Mismatch"))) -> Match | X34: =COUNTIF(U34:W34,"<>Match")+IF(T34="past closed",1,0) -> 0 | Y34: =IF(X34=0,"Clean","Review") -> Clean
A35: 001SYN000034 | B35: 006SYN000000034 | C35: FR | D35: EMEA SOUTH | E35: 36/Core+Ecom/395K/Marlow | F35: Owner ES03 | G35: Marlow Retail SAS | H35: Marlow Retail S.A.S. | I35: Consumer Products | J35: 5122 | K35: 5122 | L35: 330285644 | M35: 330285644 | N35: Tech agreement | O35: 45567 | P35: 45734 | Q35: Q1-2025 | R35: 395900 | S35: =IF(N35="Closed Won","",P35-ReportDate) -> -121 | T35: =IF(N35="Closed Won","closed",IF(S35<0,"past closed",IF(S35<=10,"update","on track"))) -> past closed | U35: =IF(H35="","No D&B match",IF(TRIM(G35)=TRIM(H35),"Match","Mismatch")) -> Mismatch | V35: =IF(K35="","No D&B match",IF(J35="","Missing in CRM",IF(J35=K35,"Match","Mismatch"))) -> Match | W35: =IF(M35="","No D&B match",IF(L35="","Missing in CRM",IF(L35=M35,"Match","Mismatch"))) -> Match | X35: =COUNTIF(U35:W35,"<>Match")+IF(T35="past closed",1,0) -> 2 | Y35: =IF(X35=0,"Clean","Review") -> Review
A36: 001SYN000035 | B36: 006SYN000000035 | C36: AE | D36: EMEA SOUTH | E36: 36/Core+Ecom/110K/North | F36: Owner ES01 | G36: North Pharma LLC | I36: Healthcare | N36: Closed Won | O36: 45620 | P36: 45682 | Q36: Q1-2025 | R36: 110500 | S36: =IF(N36="Closed Won","",P36-ReportDate) | T36: =IF(N36="Closed Won","closed",IF(S36<0,"past closed",IF(S36<=10,"update","on track"))) -> closed | U36: =IF(H36="","No D&B match",IF(TRIM(G36)=TRIM(H36),"Match","Mismatch")) -> No D&B match | V36: =IF(K36="","No D&B match",IF(J36="","Missing in CRM",IF(J36=K36,"Match","Mismatch"))) -> No D&B match | W36: =IF(M36="","No D&B match",IF(L36="","Missing in CRM",IF(L36=M36,"Match","Mismatch"))) -> No D&B match | X36: =COUNTIF(U36:W36,"<>Match")+IF(T36="past closed",1,0) -> 3 | Y36: =IF(X36=0,"Clean","Review") -> Review
A37: 001SYN000036 | B37: 006SYN000000036 | C37: US | D37: NA | E37: 12/Essentials+Mob/47K/Tavish | F37: Owner NA06 | G37: Tavish Retail Inc. | H37: Tavish Retail Inc. | I37: Automotive | J37: 4841 | K37: 5511 | L37: 955006814 | M37: 821996995 | N37: Business chemistry & scoping | O37: 45491 | P37: 45785 | Q37: Q2-2025 | R37: 47900 | S37: =IF(N37="Closed Won","",P37-ReportDate) -> -70 | T37: =IF(N37="Closed Won","closed",IF(S37<0,"past closed",IF(S37<=10,"update","on track"))) -> past closed | U37: =IF(H37="","No D&B match",IF(TRIM(G37)=TRIM(H37),"Match","Mismatch")) -> Match | V37: =IF(K37="","No D&B match",IF(J37="","Missing in CRM",IF(J37=K37,"Match","Mismatch"))) -> Mismatch | W37: =IF(M37="","No D&B match",IF(L37="","Missing in CRM",IF(L37=M37,"Match","Mismatch"))) -> Mismatch | X37: =COUNTIF(U37:W37,"<>Match")+IF(T37="past closed",1,0) -> 3 | Y37: =IF(X37=0,"Clean","Review") -> Review
A38: 001SYN000037 | B38: 006SYN000000037 | C38: AT | D38: MEE | E38: 12/Core-Adv-Omni/37K/Merrow | F38: Owner ME08 | G38: Merrow Travel GmbH | H38: Merrow Travel GmbH & Co. KG | I38: Media | J38: 4841 | K38: 4841 | L38: 558423989 | M38: 558423989 | N38: Business chemistry & scoping | O38: 45354 | P38: 45618 | Q38: Q4-2024 | R38: 37600 | S38: =IF(N38="Closed Won","",P38-ReportDate) -> -237 | T38: =IF(N38="Closed Won","closed",IF(S38<0,"past closed",IF(S38<=10,"update","on track"))) -> past closed | U38: =IF(H38="","No D&B match",IF(TRIM(G38)=TRIM(H38),"Match","Mismatch")) -> Mismatch | V38: =IF(K38="","No D&B match",IF(J38="","Missing in CRM",IF(J38=K38,"Match","Mismatch"))) -> Match | W38: =IF(M38="","No D&B match",IF(L38="","Missing in CRM",IF(L38=M38,"Match","Mismatch"))) -> Match | X38: =COUNTIF(U38:W38,"<>Match")+IF(T38="past closed",1,0) -> 2 | Y38: =IF(X38=0,"Clean","Review") -> Review
A39: 001SYN000038 | B39: 006SYN000000038 | C39: AT | D39: MEE | E39: 36/Core+Ecom+Omni/22K/Kestrel | F39: Owner ME09 | G39: Kestrel Living GmbH | I39: Media | N39: Closed Won | O39: 45622 | P39: 45768 | Q39: Q2-2025 | R39: 22800 | S39: =IF(N39="Closed Won","",P39-ReportDate) | T39: =IF(N39="Closed Won","closed",IF(S39<0,"past closed",IF(S39<=10,"update","on track"))) -> closed | U39: =IF(H39="","No D&B match",IF(TRIM(G39)=TRIM(H39),"Match","Mismatch")) -> No D&B match | V39: =IF(K39="","No D&B match",IF(J39="","Missing in CRM",IF(J39=K39,"Match","Mismatch"))) -> No D&B match | W39: =IF(M39="","No D&B match",IF(L39="","Missing in CRM",IF(L39=M39,"Match","Mismatch"))) -> No D&B match | X39: =COUNTIF(U39:W39,"<>Match")+IF(T39="past closed",1,0) -> 3 | Y39: =IF(X39=0,"Clean","Review") -> Review
A40: 001SYN000039 | B40: 006SYN000000039 | C40: CA | D40: NA | E40: 24/Core-Adv-Omni/53K/Arden | F40: Owner NA04 | G40: Arden Beauty Inc. | H40: Arden Beauty Incorporated | I40: Automotive | J40: 5511 | K40: 5511 | L40: 494163911 | M40: 494163911 | N40: Business chemistry & scoping | O40: 45595 | P40: 45721 | Q40: Q1-2025 | R40: 53400 | S40: =IF(N40="Closed Won","",P40-ReportDate) -> -134 | T40: =IF(N40="Closed Won","closed",IF(S40<0,"past closed",IF(S40<=10,"update","on track"))) -> past closed | U40: =IF(H40="","No D&B match",IF(TRIM(G40)=TRIM(H40),"Match","Mismatch")) -> Mismatch | V40: =IF(K40="","No D&B match",IF(J40="","Missing in CRM",IF(J40=K40,"Match","Mismatch"))) -> Match | W40: =IF(M40="","No D&B match",IF(L40="","Missing in CRM",IF(L40=M40,"Match","Mismatch"))) -> Match | X40: =COUNTIF(U40:W40,"<>Match")+IF(T40="past closed",1,0) -> 2 | Y40: =IF(X40=0,"Clean","Review") -> Review
...

Sheet Refresh Directions
A1: Refresh directions
A2: The routine written for the next owner of the file
A4: 1 | B4: Open the Rolling Pipeline tab and use Data > Refresh All. This pulls the latest new business opportunities for the rolling four quarters.
A5: 2 | B5: Check new rows have arrived: look for recent created dates and Opportunity IDs flagged New in column N.
A6: 3 | B6: The D&B lookup in column M matches each Opportunity ID to the account name already validated in Pipeline Compliance.
A7: 4 | B7: Copy every row flagged New into the Pipeline Compliance table and add its D&B name, SIC and DUNS from Hoovers.
A8: 5 | B8: Work the checks in columns U to W and the close date range in column T. Filter Audit status to Review.
A9: 6 | B9: Update the report date on Audit Summary, then read the regional summary before sending.
